Workbook
Name UPDATE: 'Data Sheet'!$E$1

Sheet Profit & Loss
A1: ='Data Sheet'!B1 -> ETERNAL LTD | H1: =UPDATE | M1: SCREENER.IN
A3: Narration | B3: ='Data Sheet'!B16 -> 0 | C3: ='Data Sheet'!C16 -> 43190 | D3: ='Data Sheet'!D16 -> 43555 | E3: ='Data Sheet'!E16 -> 43921 | F3: ='Data Sheet'!F16 -> 44286 | G3: ='Data Sheet'!G16 -> 44651 | H3: ='Data Sheet'!H16 -> 45016 | I3: ='Data Sheet'!I16 -> 45382 | ... K3: ='Data Sheet'!K16 -> 46112 | L3: Trailing | M3: Best Case | N3: Worst Case
A4: Sales | B4: ='Data Sheet'!B17 -> 0 | C4: ='Data Sheet'!C17 -> 466.02 | D4: ='Data Sheet'!D17 -> 1312.59 | E4: ='Data Sheet'!E17 -> 2604.74 | F4: ='Data Sheet'!F17 -> 1993.8 | G4: ='Data Sheet'!G17 -> 4192.4 | H4: ='Data Sheet'!H17 -> 7079 | I4: ='Data Sheet'!I17 -> 12114 | ... K4: ='Data Sheet'!K17 -> 54364 | L4: =SUM(Quarters!H4:K4) -> 54364 | M4: =$K4+M23*K4 -> 145998.34 | N4: =$K4+N23*L4 -> 92541.695
A5: Expenses | B5: =SUM('Data Sheet'!B18,'Data Sheet'!B20:B24, -1*'Data Sheet'!B19) -> 0 | C5: =SUM('Data Sheet'!C18,'Data Sheet'!C20:C24, -1*'Data Sheet'!C19) -> 558.47 | D5: =SUM('Data Sheet'!D18,'Data Sheet'!D20:D24, -1*'Data Sheet'!D19) -> 3556.07 | E5: =SUM('Data Sheet'!E18,'Data Sheet'!E20:E24, -1*'Data Sheet'!E19) -> 4909.44 | F5: =SUM('Data Sheet'!F18,'Data Sheet'!F20:F24, -1*'Data Sheet'!F19) -> 2460.9 | G5: =SUM('Data Sheet'!G18,'Data Sheet'!G20:G24, -1*'Data Sheet'!G19) -> 6043.2 | H5: =SUM('Data Sheet'!H18,'Data Sheet'!H20:H24, -1*'Data Sheet'!H19) -> 8290 | I5: =SUM('Data Sheet'!I18,'Data Sheet'!I20:I24, -1*'Data Sheet'!I19) -> 12071 | ... K5: =SUM('Data Sheet'!K18,'Data Sheet'!K20:K24, -1*'Data Sheet'!K19) -> 53156 | L5: =SUM(Quarters!H5:K5) -> 53156 | M5: =M4-M6 -> 142754.18 | N5: =N4-N6 -> 90857.902
A6: Operating Profit | B6: =B4-B5 -> 0 | C6: =C4-C5 -> -92.45 | D6: =D4-D5 -> -2243.48 | E6: =E4-E5 -> -2304.7 | F6: =F4-F5 -> -467.1 | G6: =G4-G5 -> -1850.8 | H6: =H4-H5 -> -1211 | I6: =I4-I5 -> 43 | ... K6: =K4-K5 -> 1208 | L6: =SUM(Quarters!H6:K6) -> 1208 | M6: =M4*M24 -> 3244.1689 | N6: =N4*N24 -> 1683.7926
A7: Other Income | B7: ='Data Sheet'!B25 -> 0 | C7: ='Data Sheet'!C25 -> 21.03 | D7: ='Data Sheet'!D25 -> 1285.05 | E7: ='Data Sheet'!E25 -> 15.97 | F7: ='Data Sheet'!F25 -> -200.2 | G7: ='Data Sheet'!G25 -> 792.6 | H7: ='Data Sheet'!H25 -> 682 | I7: ='Data Sheet'!I25 -> 846 | ... K7: ='Data Sheet'!K25 -> 1396 | L7: =SUM(Quarters!H7:K7) -> 1396 | M7: 0 | N7: 0
A8: Depreciation | B8: ='Data Sheet'!B26 -> 0 | C8: ='Data Sheet'!C26 -> 29.15 | D8: ='Data Sheet'!D26 -> 43.12 | E8: ='Data Sheet'!E26 -> 84.24 | F8: ='Data Sheet'!F26 -> 137.7 | G8: ='Data Sheet'!G26 -> 150.3 | H8: ='Data Sheet'!H26 -> 437 | I8: ='Data Sheet'!I26 -> 526 | ... K8: ='Data Sheet'!K26 -> 1597 | L8: =SUM(Quarters!H8:K8) -> 1597 | M8: =+$L8 -> 1597 | N8: =+$L8 -> 1597
A9: Interest | B9: ='Data Sheet'!B27 -> 0 | C9: ='Data Sheet'!C27 -> 6.35 | D9: ='Data Sheet'!D27 -> 8.69 | E9: ='Data Sheet'!E27 -> 12.64 | F9: ='Data Sheet'!F27 -> 10.1 | G9: ='Data Sheet'!G27 -> 12 | H9: ='Data Sheet'!H27 -> 49 | I9: ='Data Sheet'!I27 -> 72 | ... K9: ='Data Sheet'!K27 -> 392 | L9: =SUM(Quarters!H9:K9) -> 392 | M9: =+$L9 -> 392 | N9: =+$L9 -> 392
A10: Profit before tax | B10: ='Data Sheet'!B28 -> 0 | C10: ='Data Sheet'!C28 -> -106.92 | D10: ='Data Sheet'!D28 -> -1010.24 | E10: ='Data Sheet'!E28 -> -2385.61 | F10: ='Data Sheet'!F28 -> -815.1 | G10: ='Data Sheet'!G28 -> -1220.5 | H10: ='Data Sheet'!H28 -> -1015 | I10: ='Data Sheet'!I28 -> 291 | ... K10: ='Data Sheet'!K28 -> 615 | L10: =SUM(Quarters!H10:K10) -> 615 | M10: =M6+M7-SUM(M8:M9) -> 1255.1689 | N10: =N6+N7-SUM(N8:N9) -> -305.20738
A11: Tax | B11: ='Data Sheet'!B29 -> 0 | C11: ='Data Sheet'!C29 -> 0 | D11: ='Data Sheet'!D29 -> 0 | E11: ='Data Sheet'!E29 -> 0 | F11: ='Data Sheet'!F29 -> 1.3 | G11: ='Data Sheet'!G29 -> 2 | H11: ='Data Sheet'!H29 -> -44 | I11: ='Data Sheet'!I29 -> -60 | ... K11: ='Data Sheet'!K29 -> 249 | L11: =SUM(Quarters!H11:K11) -> 249 | M11: =IF($L10>0,$L11/$L10,0) -> 0.40487805 | N11: =IF($L10>0,$L11/$L10,0) -> 0.40487805
A12: Net profit | B12: ='Data Sheet'!B30 -> 0 | C12: ='Data Sheet'!C30 -> -103.68 | D12: ='Data Sheet'!D30 -> -964.95 | E12: ='Data Sheet'!E30 -> -2367.16 | F12: ='Data Sheet'!F30 -> -812.8 | G12: ='Data Sheet'!G30 -> -1208.7 | H12: ='Data Sheet'!H30 -> -971 | I12: ='Data Sheet'!I30 -> 351 | ... K12: ='Data Sheet'!K30 -> 366 | L12: =SUM(Quarters!H12:K12) -> 366 | M12: =M10-M11*M10 -> 746.97859 | N12: =N10-N11*N10 -> -181.63561
A13: EPS | B13: =IF('Data Sheet'!B93>0,B12/'Data Sheet'!B93,0) -> 0 | C13: =IF('Data Sheet'!C93>0,C12/'Data Sheet'!C93,0) -> -3456 | D13: =IF('Data Sheet'!D93>0,D12/'Data Sheet'!D93,0) -> -32165 | E13: =IF('Data Sheet'!E93>0,E12/'Data Sheet'!E93,0) -> -78905.333 | F13: =IF('Data Sheet'!F93>0,F12/'Data Sheet'!F93,0) -> -20320 | G13: =IF('Data Sheet'!G93>0,G12/'Data Sheet'!G93,0) -> -1.5354616 | H13: =IF('Data Sheet'!H93>0,H12/'Data Sheet'!H93,0) -> -1.1352078 | I13: =IF('Data Sheet'!I93>0,I12/'Data Sheet'!I93,0) -> 0.39796821 | ... K13: =IF('Data Sheet'!K93>0,K12/'Data Sheet'!K93,0) -> 0.37925889 | L13: =IF('Data Sheet'!$B6>0,'Profit & Loss'!L12/'Data Sheet'!$B6,0) -> 0.3792608 | M13: =IF('Data Sheet'!$B6>0,'Profit & Loss'!M12/'Data Sheet'!$B6,0) -> 0.77404289 | N13: =IF('Data Sheet'!$B6>0,'Profit & Loss'!N12/'Data Sheet'!$B6,0) -> -0.18821658
A14: Price to earning | B14: =IF(B15>0,B15/B13,"") | C14: =IF(C15>0,C15/C13,"") | D14: =IF(D15>0,D15/D13,"") | E14: =IF(E15>0,E15/E13,"") | F14: =IF(F15>0,F15/F13,"") | G14: =IF(G15>0,G15/G13,"") -> -53.599518 | H14: =IF(H15>0,H15/H13,"") -> -44.925695 | I14: =IF(I15>0,I15/I13,"") -> 457.57424 | ... K14: =IF(K15>0,K15/K13,"") -> 603.75645 | L14: =IF(L13>0,L15/L13,0) -> 695.43175 | M14: =M25 -> 695.43175 | N14: =N25 -> 531.52864
A15: Price | B15: ='Data Sheet'!B90 -> 0 | C15: ='Data Sheet'!C90 -> 0 | D15: ='Data Sheet'!D90 -> 0 | E15: ='Data Sheet'!E90 -> 0 | F15: ='Data Sheet'!F90 -> 0 | G15: ='Data Sheet'!G90 -> 82.3 | H15: ='Data Sheet'!H90 -> 51 | I15: ='Data Sheet'!I90 -> 182.1 | ... K15: ='Data Sheet'!K90 -> 228.98 | L15: ='Data Sheet'!B8 -> 263.75 | M15: =M13*M14 -> 538.294 | N15: =N13*N14 -> -100.0425
A17: RATIOS:
A18: Dividend Payout | B18: =IF('Data Sheet'!B30>0, 'Data Sheet'!B31/'Data Sheet'!B30, 0) -> 0 | C18: =IF('Data Sheet'!C30>0, 'Data Sheet'!C31/'Data Sheet'!C30, 0) -> 0 | D18: =IF('Data Sheet'!D30>0, 'Data Sheet'!D31/'Data Sheet'!D30, 0) -> 0 | E18: =IF('Data Sheet'!E30>0, 'Data Sheet'!E31/'Data Sheet'!E30, 0) -> 0 | F18: =IF('Data Sheet'!F30>0, 'Data Sheet'!F31/'Data Sheet'!F30, 0) -> 0 | G18: =IF('Data Sheet'!G30>0, 'Data Sheet'!G31/'Data Sheet'!G30, 0) -> 0 | H18: =IF('Data Sheet'!H30>0, 'Data Sheet'!H31/'Data Sheet'!H30, 0) -> 0 | I18: =IF('Data Sheet'!I30>0, 'Data Sheet'!I31/'Data Sheet'!I30, 0) -> 0 | ... K18: =IF('Data Sheet'!K30>0, 'Data Sheet'!K31/'Data Sheet'!K30, 0) -> 0
A19: OPM | B19: =IF(B6>0,B6/B4,0) -> 0 | C19: =IF(C6>0,C6/C4,0) -> 0 | D19: =IF(D6>0,D6/D4,0) -> 0 | E19: =IF(E6>0,E6/E4,0) -> 0 | F19: =IF(F6>0,F6/F4,0) -> 0 | G19: =IF(G6>0,G6/G4,0) -> 0 | H19: =IF(H6>0,H6/H4,0) -> 0 | I19: =IF(I6>0,I6/I4,0) -> 0.003549612 | ... L19: =IF(L6>0,L6/L4,0) -> 0.022220587
G22: TRENDS: | H22: 10 YEARS | I22: 7 YEARS | J22: 5 YEARS | K22: 3 YEARS | L22: RECENT | M22: BEST | N22: WORST
G23: Sales Growth | H23: =IF(B4=0,"",POWER($K4/B4,1/9)-1) | I23: =IF(D4=0,"",POWER($K4/D4,1/7)-1) -> 0.70226059 | J23: =IF(F4=0,"",POWER($K4/F4,1/5)-1) -> 0.93698368 | K23: =IF(H4=0,"",POWER($K4/H4, 1/3)-1) -> 0.97293676 | L23: =IF(ISERROR(MAX(IF(J4=0,"",(K4-J4)/J4),IF(K4=0,"",(L4-K4)/K4))),"",MAX(IF(J4=0,"",(K4-J4)/J4),IF(K4=0,"",(L4-K4)/K4))) -> 1.6855703 | M23: =MAX(K23:L23) -> 1.6855703 | N23: =MIN(H23:L23) -> 0.70226059
G24: OPM | H24: =IF(SUM(B4:$K$4)=0,"",SUMPRODUCT(B19:$K$19,B4:$K$4)/SUM(B4:$K$4)) -> 0.018194962 | I24: =IF(SUM(E4:$K$4)=0,"",SUMPRODUCT(E19:$K$19,E4:$K$4)/SUM(E4:$K$4)) -> 0.018510406 | J24: =IF(SUM(G4:$K$4)=0,"",SUMPRODUCT(G19:$K$19,G4:$K$4)/SUM(G4:$K$4)) -> 0.019379054 | K24: =IF(SUM(I4:$K$4)=0, "", SUMPRODUCT(I19:$K$19,I4:$K$4)/SUM(I4:$K$4)) -> 0.02189781 | L24: =L19 -> 0.022220587 | M24: =MAX(K24:L24) -> 0.022220587 | N24: =MIN(H24:L24) -> 0.018194962
G25: Price to Earning | H25: =IF(ISERROR(AVERAGEIF(B14:$L14,">0")),"",AVERAGEIF(B14:$L14,">0")) -> 531.52864 | I25: =IF(ISERROR(AVERAGEIF(E14:$L14,">0")),"",AVERAGEIF(E14:$L14,">0")) -> 531.52864 | J25: =IF(ISERROR(AVERAGEIF(G14:$L14,">0")),"",AVERAGEIF(G14:$L14,">0")) -> 531.52864 | K25: =IF(ISERROR(AVERAGEIF(I14:$L14,">0")),"",AVERAGEIF(I14:$L14,">0")) -> 531.52864 | L25: =L14 -> 695.43175 | M25: =MAX(K25:L25) -> 695.43175 | N25: =MIN(H25:L25) -> 531.52864

Sheet Quarters
A1: ='Profit & Loss'!A1 -> ETERNAL LTD | E1: =UPDATE | J1: SCREENER.IN
A3: Narration | B3: ='Data Sheet'!B41 -> 45291 | C3: ='Data Sheet'!C41 -> 45382 | D3: ='Data Sheet'!D41 -> 45473 | E3: ='Data Sheet'!E41 -> 45565 | F3: ='Data Sheet'!F41 -> 45657 | G3: ='Data Sheet'!G41 -> 45747 | H3: ='Data Sheet'!H41 -> 45838 | I3: ='Data Sheet'!I41 -> 45930 | ... K3: ='Data Sheet'!K41 -> 46112
A4: Sales | B4: ='Data Sheet'!B42 -> 3288 | C4: ='Data Sheet'!C42 -> 3562 | D4: ='Data Sheet'!D42 -> 4206 | E4: ='Data Sheet'!E42 -> 4799 | F4: ='Data Sheet'!F42 -> 5405 | G4: ='Data Sheet'!G42 -> 5833 | H4: ='Data Sheet'!H42 -> 7167 | I4: ='Data Sheet'!I42 -> 13590 | ... K4: ='Data Sheet'!K42 -> 17292
A5: Expenses | B5: ='Data Sheet'!B43 -> 3237 | C5: ='Data Sheet'!C43 -> 3476 | D5: ='Data Sheet'!D43 -> 4029 | E5: ='Data Sheet'!E43 -> 4573 | F5: ='Data Sheet'!F43 -> 5243 | G5: ='Data Sheet'!G43 -> 5761 | H5: ='Data Sheet'!H43 -> 7052 | I5: ='Data Sheet'!I43 -> 13351 | ... K5: ='Data Sheet'!K43 -> 16806
A6: Operating Profit | B6: ='Data Sheet'!B50 -> 51 | C6: ='Data Sheet'!C50 -> 86 | D6: ='Data Sheet'!D50 -> 177 | E6: ='Data Sheet'!E50 -> 226 | F6: ='Data Sheet'!F50 -> 162 | G6: ='Data Sheet'!G50 -> 72 | H6: ='Data Sheet'!H50 -> 115 | I6: ='Data Sheet'!I50 -> 239 | ... K6: ='Data Sheet'!K50 -> 486
A7: Other Income | B7: ='Data Sheet'!B44 -> 219 | C7: ='Data Sheet'!C44 -> 235 | D7: ='Data Sheet'!D44 -> 236 | E7: ='Data Sheet'!E44 -> 221 | F7: ='Data Sheet'!F44 -> 252 | G7: ='Data Sheet'!G44 -> 368 | H7: ='Data Sheet'!H44 -> 354 | I7: ='Data Sheet'!I44 -> 352 | ... K7: ='Data Sheet'!K44 -> 342
A8: Depreciation | B8: ='Data Sheet'!B45 -> 128 | C8: ='Data Sheet'!C45 -> 140 | D8: ='Data Sheet'!D45 -> 149 | E8: ='Data Sheet'!E45 -> 180 | F8: ='Data Sheet'!F45 -> 247 | G8: ='Data Sheet'!G45 -> 287 | H8: ='Data Sheet'!H45 -> 314 | I8: ='Data Sheet'!I45 -> 376 | ... K8: ='Data Sheet'!K45 -> 468
A9: Interest | B9: ='Data Sheet'!B46 -> 18 | C9: ='Data Sheet'!C46 -> 20 | D9: ='Data Sheet'!D46 -> 25 | E9: ='Data Sheet'!E46 -> 30 | F9: ='Data Sheet'!F46 -> 43 | G9: ='Data Sheet'!G46 -> 56 | H9: ='Data Sheet'!H46 -> 67 | I9: ='Data Sheet'!I46 -> 86 | ... K9: ='Data Sheet'!K46 -> 132
A10: Profit before tax | B10: ='Data Sheet'!B47 -> 124 | C10: ='Data Sheet'!C47 -> 161 | D10: ='Data Sheet'!D47 -> 239 | E10: ='Data Sheet'!E47 -> 237 | F10: ='Data Sheet'!F47 -> 124 | G10: ='Data Sheet'!G47 -> 97 | H10: ='Data Sheet'!H47 -> 88 | I10: ='Data Sheet'!I47 -> 129 | ... K10: ='Data Sheet'!K47 -> 228
A11: Tax | B11: ='Data Sheet'!B48 -> -14 | C11: ='Data Sheet'!C48 -> -14 | D11: ='Data Sheet'!D48 -> -14 | E11: ='Data Sheet'!E48 -> 61 | F11: ='Data Sheet'!F48 -> 65 | G11: ='Data Sheet'!G48 -> 58 | H11: ='Data Sheet'!H48 -> 63 | I11: ='Data Sheet'!I48 -> 64 | ... K11: ='Data Sheet'!K48 -> 54
A12: Net profit | B12: ='Data Sheet'!B49 -> 138 | C12: ='Data Sheet'!C49 -> 175 | D12: ='Data Sheet'!D49 -> 253 | E12: ='Data Sheet'!E49 -> 176 | F12: ='Data Sheet'!F49 -> 59 | G12: ='Data Sheet'!G49 -> 39 | H12: ='Data Sheet'!H49 -> 25 | I12: ='Data Sheet'!I49 -> 65 | ... K12: ='Data Sheet'!K49 -> 174
A14: OPM | B14: =IF(B4>0,B6/B4,"") -> 0.015510949 | C14: =IF(C4>0,C6/C4,"") -> 0.024143739 | D14: =IF(D4>0,D6/D4,"") -> 0.042082739 | E14: =IF(E4>0,E6/E4,"") -> 0.047093144 | F14: =IF(F4>0,F6/F4,"") -> 0.029972248 | G14: =IF(G4>0,G6/G4,"") -> 0.012343562 | H14: =IF(H4>0,H6/H4,"") -> 0.016045765 | I14: =IF(I4>0,I6/I4,"") -> 0.017586461 | ... K14: =IF(K4>0,K6/K4,"") -> 0.028105482
E37: Eternal Limited (formerly known as Zomato Limited) is a major Indian technology conglomerate based in Gurugram, Haryana. It operates as the parent company for four core digital commerce businesses: Zomato (food delivery), Blinkit (quick commerce), Hyperpure (B2B supply), and District (ticketing and going-out services).

Sheet Balance Sheet
A1: ='Profit & Loss'!A1 -> ETERNAL LTD | E1: =UPDATE | J1: SCREENER.IN
A3: Narration | B3: ='Data Sheet'!B56 -> 0 | C3: ='Data Sheet'!C56 -> 43190 | D3: ='Data Sheet'!D56 -> 43555 | E3: ='Data Sheet'!E56 -> 43921 | F3: ='Data Sheet'!F56 -> 44286 | G3: ='Data Sheet'!G56 -> 44651 | H3: ='Data Sheet'!H56 -> 45016 | I3: ='Data Sheet'!I56 -> 45382 | ... K3: ='Data Sheet'!K56 -> 46112
A4: Equity Share Capital | B4: ='Data Sheet'!B57 -> 0 | C4: ='Data Sheet'!C57 -> 0.03 | D4: ='Data Sheet'!D57 -> 0.03 | E4: ='Data Sheet'!E57 -> 0.03 | F4: ='Data Sheet'!F57 -> 0 | G4: ='Data Sheet'!G57 -> 764.3 | H4: ='Data Sheet'!H57 -> 836 | I4: ='Data Sheet'!I57 -> 868 | ... K4: ='Data Sheet'!K57 -> 919
A5: Reserves | B5: ='Data Sheet'!B58 -> 0 | C5: ='Data Sheet'!C58 -> 1036.06 | D5: ='Data Sheet'!D58 -> 2355.61 | E5: ='Data Sheet'!E58 -> 457.35 | F5: ='Data Sheet'!F58 -> 7643.8 | G5: ='Data Sheet'!G58 -> 15741.2 | H5: ='Data Sheet'!H58 -> 18624 | I5: ='Data Sheet'!I58 -> 19545 | ... K5: ='Data Sheet'!K58 -> 30061
A6: Borrowings | B6: ='Data Sheet'!B59 -> 0 | C6: ='Data Sheet'!C59 -> 186.23 | D6: ='Data Sheet'!D59 -> 347.94 | E6: ='Data Sheet'!E59 -> 325.58 | F6: ='Data Sheet'!F59 -> 527.4 | G6: ='Data Sheet'!G59 -> 70.3 | H6: ='Data Sheet'!H59 -> 507 | I6: ='Data Sheet'!I59 -> 749 | ... K6: ='Data Sheet'!K59 -> 4592
A7: Other Liabilities | B7: ='Data Sheet'!B60 -> 0 | C7: ='Data Sheet'!C60 -> 152.17 | D7: ='Data Sheet'!D60 -> 709.3 | E7: ='Data Sheet'!E60 -> 2117.43 | F7: ='Data Sheet'!F60 -> 532.3 | G7: ='Data Sheet'!G60 -> 751.2 | H7: ='Data Sheet'!H60 -> 1632 | I7: ='Data Sheet'!I60 -> 2194 | ... K7: ='Data Sheet'!K60 -> 5164
A8: Total | B8: ='Data Sheet'!B61 -> 0 | C8: ='Data Sheet'!C61 -> 1374.49 | D8: ='Data Sheet'!D61 -> 3412.88 | E8: ='Data Sheet'!E61 -> 2900.39 | F8: ='Data Sheet'!F61 -> 8703.5 | G8: ='Data Sheet'!G61 -> 17327 | H8: ='Data Sheet'!H61 -> 21599 | I8: ='Data Sheet'!I61 -> 23356 | ... K8: ='Data Sheet'!K61 -> 40736
A10: Net Block | B10: ='Data Sheet'!B62 -> 0 | C10: ='Data Sheet'!C62 -> 189.8 | D10: ='Data Sheet'!D62 -> 389.08 | E10: ='Data Sheet'!E62 -> 1590.55 | F10: ='Data Sheet'!F62 -> 1539 | G10: ='Data Sheet'!G62 -> 1404.3 | H10: ='Data Sheet'!H62 -> 6344 | I10: ='Data Sheet'!I62 -> 6448 | ... K10: ='Data Sheet'!K62 -> 12675
A11: Capital Work in Progress | B11: ='Data Sheet'!B63 -> 0 | C11: ='Data Sheet'!C63 -> 1.29 | D11: ='Data Sheet'!D63 -> 0.74 | E11: ='Data Sheet'!E63 -> 0.96 | F11: ='Data Sheet'!F63 -> 0.1 | G11: ='Data Sheet'!G63 -> 0.6 | H11: ='Data Sheet'!H63 -> 7 | I11: ='Data Sheet'!I63 -> 18 | ... K11: ='Data Sheet'!K63 -> 136
A12: Investments | B12: ='Data Sheet'!B64 -> 0 | C12: ='Data Sheet'!C64 -> 829.23 | D12: ='Data Sheet'!D64 -> 2144.55 | E12: ='Data Sheet'!E64 -> 323.92 | F12: ='Data Sheet'!F64 -> 2205.2 | G12: ='Data Sheet'!G64 -> 4717.7 | H12: ='Data Sheet'!H64 -> 6765 | I12: ='Data Sheet'!I64 -> 11645 | ... K12: ='Data Sheet'!K64 -> 14833
A13: Other Assets | B13: ='Data Sheet'!B65 -> 0 | C13: ='Data Sheet'!C65 -> 354.17 | D13: ='Data Sheet'!D65 -> 878.51 | E13: ='Data Sheet'!E65 -> 984.96 | F13: ='Data Sheet'!F65 -> 4959.2 | G13: ='Data Sheet'!G65 -> 11204.4 | H13: ='Data Sheet'!H65 -> 8483 | I13: ='Data Sheet'!I65 -> 5245 | ... K13: ='Data Sheet'!K65 -> 13092
A14: Total | B14: ='Data Sheet'!B66 -> 0 | C14: ='Data Sheet'!C66 -> 1374.49 | D14: ='Data Sheet'!D66 -> 3412.88 | E14: ='Data Sheet'!E66 -> 2900.39 | F14: ='Data Sheet'!F66 -> 8703.5 | G14: ='Data Sheet'!G66 -> 17327 | H14: ='Data Sheet'!H66 -> 21599 | I14: ='Data Sheet'!I66 -> 23356 | ... K14: ='Data Sheet'!K66 -> 40736
A16: Working Capital | B16: =B13-B7 -> 0 | C16: =C13-C7 -> 202 | D16: =D13-D7 -> 169.21 | E16: =E13-E7 -> -1132.47 | F16: =F13-F7 -> 4426.9 | G16: =G13-G7 -> 10453.2 | H16: =H13-H7 -> 6851 | I16: =I13-I7 -> 3051 | ... K16: =K13-K7 -> 7928
A17: Debtors | B17: ='Data Sheet'!B67 -> 0 | C17: ='Data Sheet'!C67 -> 26.08 | D17: ='Data Sheet'!D67 -> 70.34 | E17: ='Data Sheet'!E67 -> 123.12 | F17: ='Data Sheet'!F67 -> 129.9 | G17: ='Data Sheet'!G67 -> 159.9 | H17: ='Data Sheet'!H67 -> 457 | I17: ='Data Sheet'!I67 -> 794 | ... K17: ='Data Sheet'!K67 -> 1764
A18: Inventory | B18: ='Data Sheet'!B68 -> 0 | C18: ='Data Sheet'!C68 -> 0 | D18: ='Data Sheet'!D68 -> 2.13 | E18: ='Data Sheet'!E68 -> 3.73 | F18: ='Data Sheet'!F68 -> 14.8 | G18: ='Data Sheet'!G68 -> 39.7 | H18: ='Data Sheet'!H68 -> 83 | I18: ='Data Sheet'!I68 -> 88 | ... K18: ='Data Sheet'!K68 -> 2181
A20: Debtor Days | B20: =IF('Profit & Loss'!B4>0,'Balance Sheet'!B17/('Profit & Loss'!B4/365),0) -> 0 | C20: =IF('Profit & Loss'!C4>0,'Balance Sheet'!C17/('Profit & Loss'!C4/365),0) -> 20.426591 | D20: =IF('Profit & Loss'!D4>0,'Balance Sheet'!D17/('Profit & Loss'!D4/365),0) -> 19.559878 | E20: =IF('Profit & Loss'!E4>0,'Balance Sheet'!E17/('Profit & Loss'!E4/365),0) -> 17.252701 | F20: =IF('Profit & Loss'!F4>0,'Balance Sheet'!F17/('Profit & Loss'!F4/365),0) -> 23.780469 | G20: =IF('Profit & Loss'!G4>0,'Balance Sheet'!G17/('Profit & Loss'!G4/365),0) -> 13.921262 | H20: =IF('Profit & Loss'!H4>0,'Balance Sheet'!H17/('Profit & Loss'!H4/365),0) -> 23.563356 | I20: =IF('Profit & Loss'!I4>0,'Balance Sheet'!I17/('Profit & Loss'!I4/365),0) -> 23.92356 | ... K20: =IF('Profit & Loss'!K4>0,'Balance Sheet'!K17/('Profit & Loss'!K4/365),0) -> 11.843499
A21: Inventory Turnover | B21: =IF('Balance Sheet'!B18>0,'Profit & Loss'!B4/'Balance Sheet'!B18,0) -> 0 | C21: =IF('Balance Sheet'!C18>0,'Profit & Loss'!C4/'Balance Sheet'!C18,0) -> 0 | D21: =IF('Balance Sheet'!D18>0,'Profit & Loss'!D4/'Balance Sheet'!D18,0) -> 616.23944 | E21: =IF('Balance Sheet'!E18>0,'Profit & Loss'!E4/'Balance Sheet'!E18,0) -> 698.32172 | F21: =IF('Balance Sheet'!F18>0,'Profit & Loss'!F4/'Balance Sheet'!F18,0) -> 134.71622 | G21: =IF('Balance Sheet'!G18>0,'Profit & Loss'!G4/'Balance Sheet'!G18,0) -> 105.60202 | H21: =IF('Balance Sheet'!H18>0,'Profit & Loss'!H4/'Balance Sheet'!H18,0) -> 85.289157 | I21: =IF('Balance Sheet'!I18>0,'Profit & Loss'!I4/'Balance Sheet'!I18,0) -> 137.65909 | ... K21: =IF('Balance Sheet'!K18>0,'Profit & Loss'!K4/'Balance Sheet'!K18,0) -> 24.926181
A23: Return on Equity | B23: =IF(SUM('Balance Sheet'!B4:B5)>0,'Profit & Loss'!B12/SUM('Balance Sheet'!B4:B5),"") | C23: =IF(SUM('Balance Sheet'!C4:C5)>0,'Profit & Loss'!C12/SUM('Balance Sheet'!C4:C5),"") -> -0.10006853 | D23: =IF(SUM('Balance Sheet'!D4:D5)>0,'Profit & Loss'!D12/SUM('Balance Sheet'!D4:D5),"") -> -0.4096339 | E23: =IF(SUM('Balance Sheet'!E4:E5)>0,'Profit & Loss'!E12/SUM('Balance Sheet'!E4:E5),"") -> -5.1754777 | F23: =IF(SUM('Balance Sheet'!F4:F5)>0,'Profit & Loss'!F12/SUM('Balance Sheet'!F4:F5),"") -> -0.10633455 | G23: =IF(SUM('Balance Sheet'!G4:G5)>0,'Profit & Loss'!G12/SUM('Balance Sheet'!G4:G5),"") -> -0.073230135 | H23: =IF(SUM('Balance Sheet'!H4:H5)>0,'Profit & Loss'!H12/SUM('Balance Sheet'!H4:H5),"") -> -0.049897225 | I23: =IF(SUM('Balance Sheet'!I4:I5)>0,'Profit & Loss'!I12/SUM('Balance Sheet'!I4:I5),"") -> 0.017194925 | ... K23: =IF(SUM('Balance Sheet'!K4:K5)>0,'Profit & Loss'!K12/SUM('Balance Sheet'!K4:K5),"") -> 0.011814074
A24: Return on Capital Emp | C24: =IF((B4+B5+B6+C4+C5+C6)>0,('Profit & Loss'!C10+'Profit & Loss'!C9)*2/(B4+B5+B6+C4+C5+C6),"") -> -0.16455593 | D24: =IF((C4+C5+C6+D4+D5+D6)>0,('Profit & Loss'!D10+'Profit & Loss'!D9)*2/(C4+C5+C6+D4+D5+D6),"") -> -0.51022695 | E24: =IF((D4+D5+D6+E4+E5+E6)>0,('Profit & Loss'!E10+'Profit & Loss'!E9)*2/(D4+D5+D6+E4+E5+E6),"") -> -1.3612177 | F24: =IF((E4+E5+E6+F4+F5+F6)>0,('Profit & Loss'!F10+'Profit & Loss'!F9)*2/(E4+E5+E6+F4+F5+F6),"") -> -0.17980469 | G24: =IF((F4+F5+F6+G4+G5+G6)>0,('Profit & Loss'!G10+'Profit & Loss'!G9)*2/(F4+F5+F6+G4+G5+G6),"") -> -0.097668404 | H24: =IF((G4+G5+G6+H4+H5+H6)>0,('Profit & Loss'!H10+'Profit & Loss'!H9)*2/(G4+G5+G6+H4+H5+H6),"") -> -0.052869512 | I24: =IF((H4+H5+H6+I4+I5+I6)>0,('Profit & Loss'!I10+'Profit & Loss'!I9)*2/(H4+H5+H6+I4+I5+I6),"") -> 0.017651779 | J24: =IF((I4+I5+I6+J4+J5+J6)>0,('Profit & Loss'!J10+'Profit & Loss'!J9)*2/(I4+I5+I6+J4+J5+J6),"") -> 0.031798819 | K24: =IF((J4+J5+J6+K4+K5+K6)>0,('Profit & Loss'!K10+'Profit & Loss'!K9)*2/(J4+J5+J6+K4+K5+K6),"") -> 0.029646422

Sheet Cash Flow
A1: ='Balance Sheet'!A1 -> ETERNAL LTD | E1: =UPDATE | J1: SCREENER.IN
A3: Narration | B3: ='Data Sheet'!B81 -> 0 | C3: ='Data Sheet'!C81 -> 43190 | D3: ='Data Sheet'!D81 -> 43555 | E3: ='Data Sheet'!E81 -> 43921 | F3: ='Data Sheet'!F81 -> 44286 | G3: ='Data Sheet'!G81 -> 44651 | H3: ='Data Sheet'!H81 -> 45016 | I3: ='Data Sheet'!I81 -> 45382 | ... K3: ='Data Sheet'!K81 -> 46112
A4: Cash from Operating Activity | B4: ='Data Sheet'!B82 -> 0 | C4: ='Data Sheet'!C82 -> 0 | D4: ='Data Sheet'!D82 -> 0 | E4: ='Data Sheet'!E82 -> -2143.63 | F4: ='Data Sheet'!F82 -> -1017.9 | G4: ='Data Sheet'!G82 -> -693 | H4: ='Data Sheet'!H82 -> -844 | I4: ='Data Sheet'!I82 -> 646 | ... K4: ='Data Sheet'!K82 -> 632
A5: Cash from Investing Activity | B5: ='Data Sheet'!B83 -> 0 | C5: ='Data Sheet'!C83 -> 0 | D5: ='Data Sheet'!D83 -> 0 | E5: ='Data Sheet'!E83 -> 1739.51 | F5: ='Data Sheet'!F83 -> -5244.6 | G5: ='Data Sheet'!G83 -> -7971 | H5: ='Data Sheet'!H83 -> 797 | I5: ='Data Sheet'!I83 -> -348 | ... K5: ='Data Sheet'!K83 -> 536
A6: Cash from Financing Activity | B6: ='Data Sheet'!B84 -> 0 | C6: ='Data Sheet'!C84 -> 0 | D6: ='Data Sheet'!D84 -> 0 | E6: ='Data Sheet'!E84 -> 358.91 | F6: ='Data Sheet'!F84 -> 6401.9 | G6: ='Data Sheet'!G84 -> 8749.8 | H6: ='Data Sheet'!H84 -> -127 | I6: ='Data Sheet'!I84 -> -207 | ... K6: ='Data Sheet'!K84 -> -842
A7: Net Cash Flow | B7: ='Data Sheet'!B85 -> 0 | C7: ='Data Sheet'!C85 -> 0 | D7: ='Data Sheet'!D85 -> 0 | E7: ='Data Sheet'!E85 -> -45.22 | F7: ='Data Sheet'!F85 -> 139.4 | G7: ='Data Sheet'!G85 -> 85.8 | H7: ='Data Sheet'!H85 -> -174 | I7: ='Data Sheet'!I85 -> 91 | ... K7: ='Data Sheet'!K85 -> 326

Sheet Customization
A1: How to use it?
A3: You can customize this workbook as you want.
B4: You can add custom formating, add conditional formating, add your own formulas… do ANYTHING.
B5: Please don't edit the "Data Sheet" only.
A7: After customization, you can upload this back on Screener.
B8: Upload on: | C8: https://www.screener.in/excel/
A10: Download your customized workbooks now onwards.
B11: Now whenever you will "Export to excel" from Screener, it will export your customized file.
A14: TESTING:
B15: This is a testing feature currently.
B16: You can report any formula errors on the worksheet at: support@screener.in

Sheet Data Sheet
A1: COMPANY NAME | B1: ETERNAL LTD | E1: =IF(B2<>B3, "A NEW VERSION OF THE WORKSHEET IS AVAILABLE", "")
A2: LATEST VERSION | B2: 2.1 | E2: PLEASE DO NOT MAKE ANY CHANGES TO THIS SHEET
A3: CURRENT VERSION | B3: 2.1
A5: META
A6: Number of shares | B6: =IF(B9>0, B9/B8, 0) -> 965.03515
A7: Face Value | B7: 1
A8: Current Price | B8: 263.75
A9: Market Capitalization | B9: 254528.02
A15: PROFIT & LOSS
A16: Report Date | C16: 43190 | D16: 43555 | E16: 43921 | F16: 44286 | G16: 44651 | H16: 45016 | I16: 45382 | J16: 45747 | K16: 46112
A17: Sales | C17: 466.02 | D17: 1312.59 | E17: 2604.74 | F17: 1993.8 | G17: 4192.4 | H17: 7079 | I17: 12114 | J17: 20243 | K17: 54364
A18: Raw Material Cost | D18: 18.72 | E18: 110.52 | F18: 202.9 | G18: 552.4 | H18: 1438 | I18: 2887 | J18: 5653 | K18: 32169
A19: Change in Inventory | D19: 2.13 | E19: 1.6 | F19: 11 | G19: 27.8 | H19: 43 | I19: 5 | J19: 88 | K19: 2002
A20: Power and Fuel | C20: 2.41 | D20: 3.17 | E20: 6.29 | F20: 1.9 | G20: 4 | H20: 23 | I20: 51 | J20: 143
A21: Other Mfr. Exp | C21: 49.81 | D21: 1339.7 | E21: 2108.91 | F21: 74.5 | G21: 183.3 | H21: 384 | I21: 521 | J21: 968
A22: Employee Cost | C22: 290.49 | D22: 600.79 | E22: 798.88 | F22: 740.8 | G22: 1633.1 | H22: 1465 | I22: 1659 | J22: 2558 | K22: 3536
A23: Selling and admin | C23: 182.17 | D23: 1514.3 | E23: 1756.34 | F23: 1435 | G23: 3654.4 | H23: 4961 | I23: 6882 | J23: 10275 | K23: 3350
A24: Other Expenses | C24: 33.59 | D24: 81.52 | E24: 130.1 | F24: 16.8 | G24: 43.8 | H24: 62 | I24: 76 | J24: 86 | K24: 16103
A25: Other Income | C25: 21.03 | D25: 1285.05 | E25: 15.97 | F25: -200.2 | G25: 792.6 | H25: 682 | I25: 846 | J25: 1066 | K25: 1396
A26: Depreciation | C26: 29.15 | D26: 43.12 | E26: 84.24 | F26: 137.7 | G26: 150.3 | H26: 437 | I26: 526 | J26: 863 | K26: 1597
A27: Interest | C27: 6.35 | D27: 8.69 | E27: 12.64 | F27: 10.1 | G27: 12 | H27: 49 | I27: 72 | J27: 154 | K27: 392
A28: Profit before tax | C28: -106.92 | D28: -1010.24 | E28: -2385.61 | F28: -815.1 | G28: -1220.5 | H28: -1015 | I28: 291 | J28: 697 | K28: 615
A29: Tax | F29: 1.3 | G29: 2 | H29: -44 | I29: -60 | J29: 170 | K29: 249
A30: Net profit | C30: -103.68 | D30: -964.95 | E30: -2367.16 | F30: -812.8 | G30: -1208.7 | H30: -971 | I30: 351 | J30: 527 | K30: 366
A31: Dividend Amount
A40: Quarters
A41: Report Date | B41: 45291 | C41: 45382 | D41: 45473 | E41: 45565 | F41: 45657 | G41: 45747 | H41: 45838 | I41: 45930 | J41: 46022 | K41: 46112
A42: Sales | B42: 3288 | C42: 3562 | D42: 4206 | E42: 4799 | F42: 5405 | G42: 5833 | H42: 7167 | I42: 13590 | J42: 16315 | K42: 17292
A43: Expenses | B43: 3237 | C43: 3476 | D43: 4029 | E43: 4573 | F43: 5243 | G43: 5761 | H43: 7052 | I43: 13351 | J43: 15947 | K43: 16806
A44: Other Income | B44: 219 | C44: 235 | D44: 236 | E44: 221 | F44: 252 | G44: 368 | H44: 354 | I44: 352 | J44: 348 | K44: 342
A45: Depreciation | B45: 128 | C45: 140 | D45: 149 | E45: 180 | F45: 247 | G45: 287 | H45: 314 | I45: 376 | J45: 439 | K45: 468
A46: Interest | B46: 18 | C46: 20 | D46: 25 | E46: 30 | F46: 43 | G46: 56 | H46: 67 | I46: 86 | J46: 107 | K46: 132
A47: Profit before tax | B47: 124 | C47: 161 | D47: 239 | E47: 237 | F47: 124 | G47: 97 | H47: 88 | I47: 129 | J47: 170 | K47: 228
A48: Tax | B48: -14 | C48: -14 | D48: -14 | E48: 61 | F48: 65 | G48: 58 | H48: 63 | I48: 64 | J48: 68 | K48: 54
A49: Net profit | B49: 138 | C49: 175 | D49: 253 | E49: 176 | F49: 59 | G49: 39 | H49: 25 | I49: 65 | J49: 102 | K49: 174
A50: Operating Profit | B50: 51 | C50: 86 | D50: 177 | E50: 226 | F50: 162 | G50: 72 | H50: 115 | I50: 239 | J50: 368 | K50: 486
A55: BALANCE SHEET
A56: Report Date | C56: 43190 | D56: 43555 | E56: 43921 | F56: 44286 | G56: 44651 | H56: 45016 | I56: 45382 | J56: 45747 | K56: 46112
A57: Equity Share Capital | C57: 0.03 | D57: 0.03 | E57: 0.03 | G57: 764.3 | H57: 836 | I57: 868 | J57: 907 | K57: 919
A58: Reserves | C58: 1036.06 | D58: 2355.61 | E58: 457.35 | F58: 7643.8 | G58: 15741.2 | H58: 18624 | I58: 19545 | J58: 29410 | K58: 30061
...

Sheet Sheet2

Sheet Sheet1
C3: Company Overview
C14: Key Financial Methodology
B15: *
B16: * | C16: Risk free rate -6.5%
B17: * | C17: Terminal rate - 6%
B18: * | C18: Growth rate- 20%
B19: * | C19: Projected period-
B20: * | C20: Tax rate-25%
B21: * | C21: Valuation Date-
C23: Financial Statements
B25: Income Statement
C27: Particulars | H27: 2022 | I27: 2023 | J27: 2024 | K27: 2025 | L27: 2026
C30: SALES | H30: ='Data Sheet'!G17 -> 4192.4 | I30: ='Data Sheet'!H17 -> 7079 | J30: ='Data Sheet'!I17 -> 12114 | K30: ='Data Sheet'!J17 -> 20243 | L30: ='Data Sheet'!K17 -> 54364
C31: sales growth(y-o-y) | I31: =I30/H30-1 -> 0.68853163 | J31: =J30/I30-1 -> 0.71125865 | K31: =K30/J30-1 -> 0.67104177 | L31: =L30/K30-1 -> 1.6855703
C32: COGS | H32: ='Data Sheet'!G18+'Data Sheet'!G20+'Data Sheet'!G21-'Data Sheet'!G19 -> 711.9 | I32: ='Data Sheet'!H18+'Data Sheet'!H20+'Data Sheet'!H21-'Data Sheet'!H19 -> 1802 | J32: ='Data Sheet'!I18+'Data Sheet'!I20+'Data Sheet'!I21-'Data Sheet'!I19 -> 3454 | K32: ='Data Sheet'!J18+'Data Sheet'!J20+'Data Sheet'!J21-'Data Sheet'!J19 -> 6676 | L32: ='Data Sheet'!K18+'Data Sheet'!K20+'Data Sheet'!K21-'Data Sheet'!K19 -> 30167
C33: % on sales | H33: =H32/H30 -> 0.16980727 | I33: =I32/I30 -> 0.25455573 | J33: =J32/J30 -> 0.28512465 | K33: =K32/K30 -> 0.32979301 | L33: =L32/L30 -> 0.55490766
C34: Gross Profit | H34: =H30-H32 -> 3480.5 | I34: =I30-I32 -> 5277 | J34: =J30-J32 -> 8660 | K34: =K30-K32 -> 13567 | L34: =L30-L32 -> 24197
C35: gross margins % | H35: =H34/H30 -> 0.83019273 | I35: =I34/I30 -> 0.74544427 | J35: =J34/J30 -> 0.71487535 | K35: =K34/K30 -> 0.67020699 | L35: =L34/L30 -> 0.44509234
C36: Operating expense | H36: ='Data Sheet'!E23+'Data Sheet'!E24 -> 1886.44 | I36: ='Data Sheet'!F23+'Data Sheet'!F24 -> 1451.8 | J36: ='Data Sheet'!G23+'Data Sheet'!G24 -> 3698.2 | K36: ='Data Sheet'!H23+'Data Sheet'!H24 -> 5023 | L36: ='Data Sheet'!I23+'Data Sheet'!I24 -> 6958
C37: % on sales | H37: =H36/H30 -> 0.44996661 | I37: =I36/I30 -> 0.20508546 | J37: =J36/J30 -> 0.30528314 | K37: =K36/K30 -> 0.24813516 | L37: =L36/L30 -> 0.12798911
C38: EBITDA | H38: =H34-H36 -> 1594.06 | I38: =I34-I36 -> 3825.2 | J38: =J34-J36 -> 4961.8 | K38: =K34-K36 -> 8544 | L38: =L34-L36 -> 17239
C39: Ebitda margins% | H39: =H38/H30 -> 0.38022612 | I39: =I38/I30 -> 0.54035881 | J39: =J38/J30 -> 0.40959221 | K39: =K38/K30 -> 0.42207183 | L39: =L38/L30 -> 0.31710323
C40: Depecitaion and amortisations | H40: ='Data Sheet'!G26 -> 150.3 | I40: ='Data Sheet'!H26 -> 437 | J40: ='Data Sheet'!I26 -> 526 | K40: ='Data Sheet'!J26 -> 863 | L40: ='Data Sheet'!K26 -> 1597
C41: EBIT | H41: =H38-H40 -> 1443.76 | I41: =I38-I40 -> 3388.2 | J41: =J38-J40 -> 4435.8 | K41: =K38-K40 -> 7681 | L41: =L38-L40 -> 15642
C42: Interest | H42: ='Data Sheet'!G27 -> 12 | I42: ='Data Sheet'!H27 -> 49 | J42: ='Data Sheet'!I27 -> 72 | K42: ='Data Sheet'!J27 -> 154 | L42: ='Data Sheet'!K27 -> 392
C43: EBT | H43: =H41-H42 -> 1431.76 | I43: =I41-I42 -> 3339.2 | J43: =J41-J42 -> 4363.8 | K43: =K41-K42 -> 7527 | L43: =L41-L42 -> 15250
C44: Tax | H44: ='Data Sheet'!G29 -> 2 | I44: ='Data Sheet'!H29 -> -44 | J44: ='Data Sheet'!I29 -> -60 | K44: ='Data Sheet'!J29 -> 170 | L44: ='Data Sheet'!K29 -> 249
C45: Net Profit | H45: =H43-H44 -> 1429.76 | I45: =I43+I44 -> 3295.2 | J45: =J43+J44 -> 4303.8 | K45: =K43-K44 -> 7357 | L45: =L43-L44 -> 15001
C46: Net Margins % | H46: =H45/H30 -> 0.34103616 | I46: =I45/I30 -> 0.46548948 | J46: =J45/J30 -> 0.35527489 | K46: =K45/K30 -> 0.36343427 | L46: =L45/L30 -> 0.27593628
C49: BALANCESHEET
D53: Particulars | I53: 2022₹ | J53: 2023₹ | K53: 2024₹ | L53: 2025₹ | M53: 2026₹
D55: Equity Share Capital | I55: 764.3 | J55: 836 | K55: 868 | L55: 907 | M55: 919
D56: Reserves | I56: 15741.2 | J56: 18624 | K56: 19545 | L56: 29410 | M56: 30061
D57: Borrowings | I57: 70.3 | J57: 507 | K57: 749 | L57: 2045 | M57: 4592
D58: Other Liabilities | I58: 751.2 | J58: 1632 | K58: 2194 | L58: 3261 | M58: 5164
D59: Total | I59: 17327 | J59: 21599 | K59: 23356 | L59: 35623 | M59: 40736
D60: Net Block | I60: 1404.3 | J60: 6344 | K60: 6448 | L60: 9532 | M60: 12675
D61: Capital Work in Progress | I61: 0.6 | J61: 7 | K61: 18 | L61: 51 | M61: 136
D62: Investments | I62: 4717.7 | J62: 6765 | K62: 11645 | L62: 13192 | M62: 14833
D63: Other Assets | I63: 11204.4 | J63: 8483 | K63: 5245 | L63: 12848 | M63: 13092
...
