Workbook
Name UPDATE: 'Data Sheet'!$E$1

Sheet Sheet1 (2)
B3: One Page profile -ITC limited
B13: KEY Financial Matrix | F13: 44651 | G13: 45016 | H13: 45382 | I13: 45747 | J13: 46112
B15: TOTAL SALES | F15: 60644.54 | G15: 70919.03 | H15: 67931.94 | I15: 75323.34 | J15: 78868.4
B16: SALES Growth(y-o-y) | F16: 0.23117498 | G16: 0.16942152 | H16: -0.042119724 | I16: 0.10880596 | J16: 0.047064562
B17: EBITDA%(Y-O-Y) | F17: 0.20852129 | G17: 0.24637895 | H17: -0.020102893 | I17: 0.025882649 | J17: 0.057217162
B18: NP(%) | F18: ='Profit & Loss'!F37 -> 0.15815211 | G18: ='Profit & Loss'!G37 -> 0.25907552 | H18: ='Profit & Loss'!H37 -> 0.066024513 | I18: ='Profit & Loss'!I37 -> 0.69837253 | J18: ='Profit & Loss'!J37 -> -0.40456182
B19: ROE% | F19: ='Balance Sheet'!G24 -> 0.24405605 | G19: ='Balance Sheet'!H24 -> 0.27751555 | H19: ='Balance Sheet'!I24 -> 0.2745887 | I19: ='Balance Sheet'!J24 -> 0.49616743 | J19: ='Balance Sheet'!K24 -> 0.28534327
B20: ROCE% | F20: ='Balance Sheet'!G25 -> 0.33733253 | G20: ='Balance Sheet'!H25 -> 0.39333609 | H20: ='Balance Sheet'!I25 -> 0.37429273 | I20: ='Balance Sheet'!J25 -> 0.57864605 | J20: ='Balance Sheet'!K25 -> 0.38725211
B22: SHAREHOLDING PATTERN | F22: =F13 -> 44651 | G22: =G13 -> 45016 | H22: =H13 -> 45382 | I22: =I13 -> 45747 | J22: =J13 -> 46112
B23: FII | F23: =Sheet2!L14 -> 0.1199 | G23: =Sheet2!M14 -> 0.4335 | H23: =Sheet2!N14 -> 0.4095 | I23: =Sheet2!O14 -> 0.3987 | J23: =Sheet2!P14 -> 0.3483
B24: DII | F24: =Sheet2!L15 -> 0.4277 | G24: =Sheet2!M15 -> 0.4208 | H24: =Sheet2!N15 -> 0.4376 | I24: =Sheet2!O15 -> 0.4519 | J24: =Sheet2!P15 -> 0.4915
B25: GOVERNMENT | F25: =Sheet2!L16 -> 0 | G25: =Sheet2!M16 -> 0.0004 | H25: =Sheet2!N16 -> 0.0004 | I25: =Sheet2!O16 -> 0.0004 | J25: =Sheet2!P16 -> 0.0004
B26: PUBLIC | F26: =Sheet2!L17 -> 0.4524 | G26: =Sheet2!M17 -> 0.1452 | H26: =Sheet2!N17 -> 0.1523 | I26: =Sheet2!O17 -> 0.149 | J26: =Sheet2!P17 -> 0.1596
B28: PEERS COMPARISON
B30: .No. | C30: Name | D30: CMP Rs. | E30: P/E | F30: Mar Cap Rs.Cr. | G30: Div Yld % | H30: NP Qtr Rs.Cr. | I30: Qtr Profit Var % | J30: Sales Qtr Rs.Cr. | K30: ROCE % | L30: Debt Rs.Cr. | M30: EV / EBIT | N30: Sales Rs.Cr.
B31: 1 | C31: Hind. Unilever | D31: 2166.4 | E31: 33.44 | F31: 509015.41 | G31: 1.89 | H31: 2994 | I31: 8.62 | J31: 16351 | K31: 28.42 | L31: 1478 | M31: 35.09 | N31: 64468
B32: 2 | C32: ITC | D32: 290.1 | E32: 17.44 | F32: 363479.77 | G32: 4.96 | H32: 5469.74 | I32: 5.3 | J32: 17824.68 | K32: 38.93 | L32: 2399.06 | M32: 12.77 | N32: 78868.4
B33: 3 | C33: Hindustan Foods | D33: 549.2 | E33: 43.67 | F33: 6654.22 | G33: 0 | H33: 41.55 | I33: 34.17 | J33: 1116.75 | K33: 14.2 | L33: 1088.26 | M33: 26.84 | N33: 4251.04
B34: 4 | C34: Godavari Bioref. | D34: 290.75 | E34: 44.24 | F34: 1487.95 | G34: 0 | H34: 52.88 | I34: -30.03 | J34: 564.1 | K34: 6.55 | L34: 530.76 | M34: 23.42 | N34: 1987.94
B35: 5 | C35: Davangere Sugar | D35: 3.59 | E35: 60.31 | F35: 513.37 | G35: 0 | H35: 1.95 | I35: 0.52 | J35: 83.82 | K35: 5.56 | L35: 250.05 | M35: 19.79 | N35: 238.77
L36: CAPITAL STRUCTURE
N37: (IN CRS)
B38: RECENT UPDATES | M38: MARKET CAPS -363225
M39: DEBT- | N39: 2399
B40: *ITC LTD said they will work on AI segment and removes the all outdated software. | M40: LESS-CASH -30008
B41: *company CEO also confirm that return on equity will grow in the mid of 15 to 20%. | L41: ENTERPRISE VALUE-= | N41: 335477
B42: *company also claim that they will aquire some few companies and want to expand in FMCG sector.
B43: *company also claim that they will probably go with FPO after this year because company needs more funds. | I43: ause company needs fresh funds.

Sheet Profit & Loss
A1: ='Data Sheet'!B1 -> ITC LTD | H1: =UPDATE | M1: SCREENER.IN
A3: Narration | B3: ='Data Sheet'!B16 -> 42825 | C3: ='Data Sheet'!C16 -> 43190 | D3: ='Data Sheet'!D16 -> 43555 | E3: ='Data Sheet'!E16 -> 43921 | F3: ='Data Sheet'!F16 -> 44286 | G3: ='Data Sheet'!G16 -> 44651 | H3: ='Data Sheet'!H16 -> 45016 | I3: ='Data Sheet'!I16 -> 45382 | ... K3: ='Data Sheet'!K16 -> 46112 | L3: Trailing | M3: Best Case | N3: Worst Case
A4: Sales | B4: ='Data Sheet'!B17 -> 42767.6 | C4: ='Data Sheet'!C17 -> 43448.94 | D4: ='Data Sheet'!D17 -> 48339.58 | E4: ='Data Sheet'!E17 -> 49387.7 | F4: ='Data Sheet'!F17 -> 49257.45 | G4: ='Data Sheet'!G17 -> 60644.54 | H4: ='Data Sheet'!H17 -> 70919.03 | I4: ='Data Sheet'!I17 -> 67931.94 | ... K4: ='Data Sheet'!K17 -> 78868.4 | L4: =SUM(Quarters!H4:K4) -> 78868.4 | M4: =$K4+M23*K4 -> 82580.307 | N4: =$K4+N23*L4 -> 81711.487
A5: Expenses | B5: =SUM('Data Sheet'!B18,'Data Sheet'!B20:B24, -1*'Data Sheet'!B19) -> 27298.09 | C5: =SUM('Data Sheet'!C18,'Data Sheet'!C20:C24, -1*'Data Sheet'!C19) -> 26928.35 | D5: =SUM('Data Sheet'!D18,'Data Sheet'!D20:D24, -1*'Data Sheet'!D19) -> 29802.19 | E5: =SUM('Data Sheet'!E18,'Data Sheet'!E20:E24, -1*'Data Sheet'!E19) -> 30044.16 | F5: =SUM('Data Sheet'!F18,'Data Sheet'!F20:F24, -1*'Data Sheet'!F19) -> 32192.67 | G5: =SUM('Data Sheet'!G18,'Data Sheet'!G20:G24, -1*'Data Sheet'!G19) -> 40021.39 | H5: =SUM('Data Sheet'!H18,'Data Sheet'!H20:H24, -1*'Data Sheet'!H19) -> 45214.77 | I5: =SUM('Data Sheet'!I18,'Data Sheet'!I20:I24, -1*'Data Sheet'!I19) -> 42744.41 | ... K5: =SUM('Data Sheet'!K18,'Data Sheet'!K20:K24, -1*'Data Sheet'!K19) -> 51550.49 | L5: =SUM(Quarters!H5:K5) -> 51550.49 | M5: =M4-M6 -> 53453.538 | N5: =N4-N6 -> 53408.807
A6: Operating Profit | B6: =B4-B5 -> 15469.51 | C6: =C4-C5 -> 16520.59 | D6: =D4-D5 -> 18537.39 | E6: =E4-E5 -> 19343.54 | F6: =F4-F5 -> 17064.78 | G6: =G4-G5 -> 20623.15 | H6: =H4-H5 -> 25704.26 | I6: =I4-I5 -> 25187.53 | ... K6: =K4-K5 -> 27317.91 | L6: =SUM(Quarters!H6:K6) -> 27317.91 | M6: =M4*M24 -> 29126.769 | N6: =N4*N24 -> 28302.679
A7: Other Income | B7: ='Data Sheet'!B25 -> 1758.63 | C7: ='Data Sheet'!C25 -> 2239.81 | D7: ='Data Sheet'!D25 -> 2080.44 | E7: ='Data Sheet'!E25 -> 2417.32 | F7: ='Data Sheet'!F25 -> 2576.95 | G7: ='Data Sheet'!G25 -> 1909.72 | H7: ='Data Sheet'!H25 -> 2097.64 | I7: ='Data Sheet'!I25 -> 3330.45 | ... K7: ='Data Sheet'!K25 -> 2511.18 | L7: =SUM(Quarters!H7:K7) -> 2511.18 | M7: 0 | N7: 0
A8: Depreciation | B8: ='Data Sheet'!B26 -> 1152.79 | C8: ='Data Sheet'!C26 -> 1236.28 | D8: ='Data Sheet'!D26 -> 1396.61 | E8: ='Data Sheet'!E26 -> 1644.91 | F8: ='Data Sheet'!F26 -> 1645.59 | G8: ='Data Sheet'!G26 -> 1732.41 | H8: ='Data Sheet'!H26 -> 1809.01 | I8: ='Data Sheet'!I26 -> 1518.05 | ... K8: ='Data Sheet'!K26 -> 1710.53 | L8: =SUM(Quarters!H8:K8) -> 1710.53 | M8: =+$L8 -> 1710.53 | N8: =+$L8 -> 1710.53
A9: Interest | B9: ='Data Sheet'!B27 -> 49.03 | C9: ='Data Sheet'!C27 -> 115.01 | D9: ='Data Sheet'!D27 -> 71.4 | E9: ='Data Sheet'!E27 -> 81.38 | F9: ='Data Sheet'!F27 -> 57.97 | G9: ='Data Sheet'!G27 -> 59.99 | H9: ='Data Sheet'!H27 -> 77.77 | I9: ='Data Sheet'!I27 -> 39.11 | ... K9: ='Data Sheet'!K27 -> 85.17 | L9: =SUM(Quarters!H9:K9) -> 85.17 | M9: =+$L9 -> 85.17 | N9: =+$L9 -> 85.17
A10: Profit before tax | B10: ='Data Sheet'!B28 -> 16026.32 | C10: ='Data Sheet'!C28 -> 17409.11 | D10: ='Data Sheet'!D28 -> 19149.82 | E10: ='Data Sheet'!E28 -> 20034.57 | F10: ='Data Sheet'!F28 -> 17938.17 | G10: ='Data Sheet'!G28 -> 20740.47 | H10: ='Data Sheet'!H28 -> 25915.12 | I10: ='Data Sheet'!I28 -> 26960.82 | ... K10: ='Data Sheet'!K28 -> 28033.39 | L10: =SUM(Quarters!H10:K10) -> 28033.39 | M10: =M6+M7-SUM(M8:M9) -> 27331.069 | N10: =N6+N7-SUM(N8:N9) -> 26506.979
A11: Tax | B11: ='Data Sheet'!B29 -> 5549.09 | C11: ='Data Sheet'!C29 -> 5916.43 | D11: ='Data Sheet'!D29 -> 6313.92 | E11: ='Data Sheet'!E29 -> 4441.79 | F11: ='Data Sheet'!F29 -> 4555.29 | G11: ='Data Sheet'!G29 -> 5237.34 | H11: ='Data Sheet'!H29 -> 6438.4 | I11: ='Data Sheet'!I29 -> 6209.46 | ... K11: ='Data Sheet'!K29 -> 7015.24 | L11: =SUM(Quarters!H11:K11) -> 7015.24 | M11: =IF($L10>0,$L11/$L10,0) -> 0.25024587 | N11: =IF($L10>0,$L11/$L10,0) -> 0.25024587
A12: Net profit | B12: ='Data Sheet'!B30 -> 10289.44 | C12: ='Data Sheet'!C30 -> 11271.2 | D12: ='Data Sheet'!D30 -> 12592.33 | E12: ='Data Sheet'!E30 -> 15306.23 | F12: ='Data Sheet'!F30 -> 13161.19 | G12: ='Data Sheet'!G30 -> 15242.66 | H12: ='Data Sheet'!H30 -> 19191.66 | I12: ='Data Sheet'!I30 -> 20458.78 | ... K12: ='Data Sheet'!K30 -> 20689.47 | L12: =SUM(Quarters!H12:K12) -> 20689.47 | M12: =M10-M11*M10 -> 20491.582 | N12: =N10-N11*N10 -> 19873.717
A13: EPS | B13: =IF('Data Sheet'!B93>0,B12/'Data Sheet'!B93,0) -> 8.4704875 | C13: =IF('Data Sheet'!C93>0,C12/'Data Sheet'!C93,0) -> 9.2354334 | D13: =IF('Data Sheet'!D93>0,D12/'Data Sheet'!D93,0) -> 10.272242 | E13: =IF('Data Sheet'!E93>0,E12/'Data Sheet'!E93,0) -> 12.451986 | F13: =IF('Data Sheet'!F93>0,F12/'Data Sheet'!F93,0) -> 10.692505 | G13: =IF('Data Sheet'!G93>0,G12/'Data Sheet'!G93,0) -> 12.368976 | H13: =IF('Data Sheet'!H93>0,H12/'Data Sheet'!H93,0) -> 15.442276 | I13: =IF('Data Sheet'!I93>0,I12/'Data Sheet'!I93,0) -> 16.387082 | ... K13: =IF('Data Sheet'!K93>0,K12/'Data Sheet'!K93,0) -> 16.512606 | L13: =IF('Data Sheet'!$B6>0,'Profit & Loss'!L12/'Data Sheet'!$B6,0) -> 16.512651 | M13: =IF('Data Sheet'!$B6>0,'Profit & Loss'!M12/'Data Sheet'!$B6,0) -> 16.354713 | N13: =IF('Data Sheet'!$B6>0,'Profit & Loss'!N12/'Data Sheet'!$B6,0) -> 15.861584
A14: Price to earning | B14: =IF(B15>0,B15/B13,"") -> 31.019466 | C14: =IF(C15>0,C15/C13,"") -> 25.93273 | D14: =IF(D15>0,D15/D13,"") -> 27.12553 | E14: =IF(E15>0,E15/E13,"") -> 12.925649 | F14: =IF(F15>0,F15/F13,"") -> 19.155475 | G14: =IF(G15>0,G15/G13,"") -> 18.995914 | H14: =IF(H15>0,H15/H13,"") -> 23.2796 | I14: =IF(I15>0,I15/I13,"") -> 24.502837 | ... K14: =IF(K15>0,K15/K13,"") -> 17.423052 | L14: =IF(L13>0,L15/L13,0) -> 17.668271 | M14: =M25 -> 18.587857 | N14: =N25 -> 17.668271
A15: Price | B15: ='Data Sheet'!B90 -> 262.75 | C15: ='Data Sheet'!C90 -> 239.5 | D15: ='Data Sheet'!D90 -> 278.64 | E15: ='Data Sheet'!E90 -> 160.95 | F15: ='Data Sheet'!F90 -> 204.82 | G15: ='Data Sheet'!G90 -> 234.96 | H15: ='Data Sheet'!H90 -> 359.49 | I15: ='Data Sheet'!I90 -> 401.53 | ... K15: ='Data Sheet'!K90 -> 287.7 | L15: ='Data Sheet'!B8 -> 291.75 | M15: =M13*M14 -> 303.99906 | N15: =N13*N14 -> 280.24676
A17: RATIOS:
A18: Dividend Payout | B18: =IF('Data Sheet'!B30>0, 'Data Sheet'!B31/'Data Sheet'!B30, 0) -> 0.56077104 | C18: =IF('Data Sheet'!C30>0, 'Data Sheet'!C31/'Data Sheet'!C30, 0) -> 0.5576345 | D18: =IF('Data Sheet'!D30>0, 'Data Sheet'!D31/'Data Sheet'!D30, 0) -> 0.55976138 | E18: =IF('Data Sheet'!E30>0, 'Data Sheet'!E31/'Data Sheet'!E30, 0) -> 0.81513083 | F18: =IF('Data Sheet'!F30>0, 'Data Sheet'!F31/'Data Sheet'!F30, 0) -> 1.0053772 | G18: =IF('Data Sheet'!G30>0, 'Data Sheet'!G31/'Data Sheet'!G30, 0) -> 0.92974586 | H18: =IF('Data Sheet'!H30>0, 'Data Sheet'!H31/'Data Sheet'!H30, 0) -> 1.0037381 | I18: =IF('Data Sheet'!I30>0, 'Data Sheet'!I31/'Data Sheet'!I30, 0) -> 0.83907545 | ... K18: =IF('Data Sheet'!K30>0, 'Data Sheet'!K31/'Data Sheet'!K30, 0) -> 0.87811723
A19: OPM | B19: =IF(B6>0,B6/B4,0) -> 0.36171097 | C19: =IF(C6>0,C6/C4,0) -> 0.38022999 | D19: =IF(D6>0,D6/D4,0) -> 0.38348265 | E19: =IF(E6>0,E6/E4,0) -> 0.39166716 | F19: =IF(F6>0,F6/F4,0) -> 0.34644059 | G19: =IF(G6>0,G6/G4,0) -> 0.34006606 | H19: =IF(H6>0,H6/H4,0) -> 0.36244517 | I19: =IF(I6>0,I6/I4,0) -> 0.37077596 | ... L19: =IF(L6>0,L6/L4,0) -> 0.34637333
G22: TRENDS: | H22: 10 YEARS | I22: 7 YEARS | J22: 5 YEARS | K22: 3 YEARS | L22: RECENT | M22: BEST | N22: WORST
G23: Sales Growth | H23: =IF(B4=0,"",POWER($K4/B4,1/9)-1) -> 0.070365289 | I23: =IF(D4=0,"",POWER($K4/D4,1/7)-1) -> 0.072436165 | J23: =IF(F4=0,"",POWER($K4/F4,1/5)-1) -> 0.098717953 | K23: =IF(H4=0,"",POWER($K4/H4, 1/3)-1) -> 0.036048488 | L23: =IF(ISERROR(MAX(IF(J4=0,"",(K4-J4)/J4),IF(K4=0,"",(L4-K4)/K4))),"",MAX(IF(J4=0,"",(K4-J4)/J4),IF(K4=0,"",(L4-K4)/K4))) -> 0.047064562 | M23: =MAX(K23:L23) -> 0.047064562 | N23: =MIN(H23:L23) -> 0.036048488
G24: OPM | H24: =IF(SUM(B4:$K$4)=0,"",SUMPRODUCT(B19:$K$19,B4:$K$4)/SUM(B4:$K$4)) -> 0.36055929 | I24: =IF(SUM(E4:$K$4)=0,"",SUMPRODUCT(E19:$K$19,E4:$K$4)/SUM(E4:$K$4)) -> 0.35611117 | J24: =IF(SUM(G4:$K$4)=0,"",SUMPRODUCT(G19:$K$19,G4:$K$4)/SUM(G4:$K$4)) -> 0.35249306 | K24: =IF(SUM(I4:$K$4)=0, "", SUMPRODUCT(I19:$K$19,I4:$K$4)/SUM(I4:$K$4)) -> 0.35270841 | L24: =L19 -> 0.34637333 | M24: =MAX(K24:L24) -> 0.35270841 | N24: =MIN(H24:L24) -> 0.34637333
G25: Price to Earning | H25: =IF(ISERROR(AVERAGEIF(B14:$L14,">0")),"",AVERAGEIF(B14:$L14,">0")) -> 21.162345 | I25: =IF(ISERROR(AVERAGEIF(E14:$L14,">0")),"",AVERAGEIF(E14:$L14,">0")) -> 18.588508 | J25: =IF(ISERROR(AVERAGEIF(G14:$L14,">0")),"",AVERAGEIF(G14:$L14,">0")) -> 19.437823 | K25: =IF(ISERROR(AVERAGEIF(I14:$L14,">0")),"",AVERAGEIF(I14:$L14,">0")) -> 18.587857 | L25: =L14 -> 17.668271 | M25: =MAX(K25:L25) -> 18.587857 | N25: =MIN(H25:L25) -> 17.668271
A32: Sales growth % | D32: =G4/F4-1 -> 0.23117498 | E32: =H4/G4-1 -> 0.16942152 | F32: =I4/H4-1 -> -0.042119724 | G32: =J4/I4-1 -> 0.10880596 | H32: =K4/J4-1 -> 0.047064562 | I32: =L4/K4-1 -> 0
A34: EBITDA % | D34: =G6/F6-1 -> 0.20852129 | E34: =H6/G6-1 -> 0.24637895 | F34: =I6/H6-1 -> -0.020102893 | G34: =J6/I6-1 -> 0.025882649 | H34: =K6/J6-1 -> 0.057217162 | I34: =L6/K6-1 -> 0
A37: NP% | F37: =G12/F12-1 -> 0.15815211 | G37: =H12/G12-1 -> 0.25907552 | H37: =I12/H12-1 -> 0.066024513 | I37: =J12/I12-1 -> 0.69837253 | J37: =K12/J12-1 -> -0.40456182

Sheet Sheet2
F8: olding Pattern
F9: Numbers in percentages
F11: QuarterlyYearly
F12: Trades
G13: 42795 | H13: 43160 | I13: 43525 | J13: 43891 | K13: 44256 | L13: 44621 | M13: 44986 | N13: 45352 | O13: 45717 | P13: 46082
F14: FIIs + | G14: 0.2008 | H14: 0.18 | I14: 0.1704 | J14: 0.1465 | K14: 0.1279 | L14: 0.1199 | M14: 0.4335 | N14: 0.4095 | O14: 0.3987 | P14: 0.3483
F15: DIIs + | G15: 0.3579 | H15: 0.371 | I15: 0.382 | J15: 0.4246 | K15: 0.425 | L15: 0.4277 | M15: 0.4208 | N15: 0.4376 | O15: 0.4519 | P15: 0.4915
F16: Government + | G16: 0 | H16: 0 | I16: 0 | J16: 0 | K16: 0 | L16: 0 | M16: 0.0004 | N16: 0.0004 | O16: 0.0004 | P16: 0.0004
F17: Public + | G17: 0.4413 | H17: 0.449 | I17: 0.4476 | J17: 0.4289 | K17: 0.4471 | L17: 0.4524 | M17: 0.1452 | N17: 0.1523 | O17: 0.149 | P17: 0.1596
F18: No. of Shareholders | G18: 5,47,642 | H18: 7,95,843 | I18: 8,57,729 | J18: 13,02,214 | K18: 21,96,475 | L18: 28,40,964 | M18: 29,30,527 | N18: 36,48,537 | O18: 36,47,886 | P18: 40,41,653
F27: .No. | G27: Name | H27: CMP Rs. | I27: P/E | J27: Mar Cap Rs.Cr. | K27: Div Yld % | L27: NP Qtr Rs.Cr. | M27: Qtr Profit Var % | N27: Sales Qtr Rs.Cr. | O27: ROCE % | P27: Debt Rs.Cr. | Q27: EV / EBIT | R27: Sales Rs.Cr.
F28: 1 | G28: Hind. Unilever | H28: 2166.4 | I28: 33.44 | J28: 509015.41 | K28: 1.89 | L28: 2994 | M28: 8.62 | N28: 16351 | O28: 28.42 | P28: 1478 | Q28: 35.09 | R28: 64468
F29: 2 | G29: ITC | H29: 290.1 | I29: 17.44 | J29: 363479.77 | K29: 4.96 | L29: 5469.74 | M29: 5.3 | N29: 17824.68 | O29: 38.93 | P29: 2399.06 | Q29: 12.77 | R29: 78868.4
F30: 3 | G30: Hindustan Foods | H30: 549.2 | I30: 43.67 | J30: 6654.22 | K30: 0 | L30: 41.55 | M30: 34.17 | N30: 1116.75 | O30: 14.2 | P30: 1088.26 | Q30: 26.84 | R30: 4251.04
F31: 4 | G31: Godavari Bioref. | H31: 290.75 | I31: 44.24 | J31: 1487.95 | K31: 0 | L31: 52.88 | M31: -30.03 | N31: 564.1 | O31: 6.55 | P31: 530.76 | Q31: 23.42 | R31: 1987.94
F32: 5 | G32: Davangere Sugar | H32: 3.59 | I32: 60.31 | J32: 513.37 | K32: 0 | L32: 1.95 | M32: 0.52 | N32: 83.82 | O32: 5.56 | P32: 250.05 | Q32: 19.79 | R32: 238.77

Sheet Quarters
A1: ='Profit & Loss'!A1 -> ITC LTD | E1: =UPDATE | J1: SCREENER.IN
A3: Narration | B3: ='Data Sheet'!B41 -> 45291 | C3: ='Data Sheet'!C41 -> 45382 | D3: ='Data Sheet'!D41 -> 45473 | E3: ='Data Sheet'!E41 -> 45565 | F3: ='Data Sheet'!F41 -> 45657 | G3: ='Data Sheet'!G41 -> 45747 | H3: ='Data Sheet'!H41 -> 45838 | I3: ='Data Sheet'!I41 -> 45930 | ... K3: ='Data Sheet'!K41 -> 46112
A4: Sales | B4: ='Data Sheet'!B42 -> 17195.24 | C4: ='Data Sheet'!C42 -> 17037.8 | D4: ='Data Sheet'!D42 -> 17777.81 | E4: ='Data Sheet'!E42 -> 19990.36 | F4: ='Data Sheet'!F42 -> 18790.17 | G4: ='Data Sheet'!G42 -> 18765 | H4: ='Data Sheet'!H42 -> 21494.79 | I4: ='Data Sheet'!I42 -> 19501.63 | ... K4: ='Data Sheet'!K42 -> 17824.68
A5: Expenses | B5: ='Data Sheet'!B43 -> 10985.01 | C5: ='Data Sheet'!C43 -> 10735.73 | D5: ='Data Sheet'!D43 -> 11232.97 | E5: ='Data Sheet'!E43 -> 13438.28 | F5: ='Data Sheet'!F43 -> 12428.27 | G5: ='Data Sheet'!G43 -> 12245.61 | H5: ='Data Sheet'!H43 -> 14678.32 | I5: ='Data Sheet'!I43 -> 12806.94 | ... K5: ='Data Sheet'!K43 -> 10900.45
A6: Operating Profit | B6: ='Data Sheet'!B50 -> 6210.23 | C6: ='Data Sheet'!C50 -> 6302.07 | D6: ='Data Sheet'!D50 -> 6544.84 | E6: ='Data Sheet'!E50 -> 6552.08 | F6: ='Data Sheet'!F50 -> 6361.9 | G6: ='Data Sheet'!G50 -> 6519.39 | H6: ='Data Sheet'!H50 -> 6816.47 | I6: ='Data Sheet'!I50 -> 6694.69 | ... K6: ='Data Sheet'!K50 -> 6924.23
A7: Other Income | B7: ='Data Sheet'!B44 -> 820.26 | C7: ='Data Sheet'!C44 -> 868 | D7: ='Data Sheet'!D44 -> 771.13 | E7: ='Data Sheet'!E44 -> 690.31 | F7: ='Data Sheet'!F44 -> 803.4 | G7: ='Data Sheet'!G44 -> 15391.28 | H7: ='Data Sheet'!H44 -> 750.97 | I7: ='Data Sheet'!I44 -> 738.84 | ... K7: ='Data Sheet'!K44 -> 699.52
A8: Depreciation | B8: ='Data Sheet'!B45 -> 384.04 | C8: ='Data Sheet'!C45 -> 385.09 | D8: ='Data Sheet'!D45 -> 403.13 | E8: ='Data Sheet'!E45 -> 416.18 | F8: ='Data Sheet'!F45 -> 415.98 | G8: ='Data Sheet'!G45 -> 411.03 | H8: ='Data Sheet'!H45 -> 422.96 | I8: ='Data Sheet'!I45 -> 434.8 | ... K8: ='Data Sheet'!K45 -> 421.95
A9: Interest | B9: ='Data Sheet'!B46 -> 11.94 | C9: ='Data Sheet'!C46 -> 10.72 | D9: ='Data Sheet'!D46 -> 9.6 | E9: ='Data Sheet'!E46 -> 14.73 | F9: ='Data Sheet'!F46 -> 9.82 | G9: ='Data Sheet'!G46 -> 10.91 | H9: ='Data Sheet'!H46 -> 16.47 | I9: ='Data Sheet'!I46 -> 20.05 | ... K9: ='Data Sheet'!K46 -> 29.18
A10: Profit before tax | B10: ='Data Sheet'!B47 -> 6634.51 | C10: ='Data Sheet'!C47 -> 6774.26 | D10: ='Data Sheet'!D47 -> 6903.24 | E10: ='Data Sheet'!E47 -> 6811.48 | F10: ='Data Sheet'!F47 -> 6739.5 | G10: ='Data Sheet'!G47 -> 21488.73 | H10: ='Data Sheet'!H47 -> 7128.01 | I10: ='Data Sheet'!I47 -> 6978.68 | ... K10: ='Data Sheet'!K47 -> 7172.62
A11: Tax | B11: ='Data Sheet'!B48 -> 1227.99 | C11: ='Data Sheet'!C48 -> 1583.55 | D11: ='Data Sheet'!D48 -> 1726.25 | E11: ='Data Sheet'!E48 -> 1757.05 | F11: ='Data Sheet'!F48 -> 1726.32 | G11: ='Data Sheet'!G48 -> 1680.85 | H11: ='Data Sheet'!H48 -> 1784.6 | I11: ='Data Sheet'!I48 -> 1792.13 | ... K11: ='Data Sheet'!K48 -> 1702.88
A12: Net profit | B12: ='Data Sheet'!B49 -> 5335.23 | C12: ='Data Sheet'!C49 -> 5120.55 | D12: ='Data Sheet'!D49 -> 5091.59 | E12: ='Data Sheet'!E49 -> 4992.87 | F12: ='Data Sheet'!F49 -> 4934.8 | G12: ='Data Sheet'!G49 -> 19727.37 | H12: ='Data Sheet'!H49 -> 5244.2 | I12: ='Data Sheet'!I49 -> 5126.11 | ... K12: ='Data Sheet'!K49 -> 5387.97
A14: OPM | B14: =IF(B4>0,B6/B4,"") -> 0.36115983 | C14: =IF(C4>0,C6/C4,"") -> 0.36988754 | D14: =IF(D4>0,D6/D4,"") -> 0.36814658 | E14: =IF(E4>0,E6/E4,"") -> 0.32776198 | F14: =IF(F4>0,F6/F4,"") -> 0.33857597 | G14: =IF(G4>0,G6/G4,"") -> 0.34742286 | H14: =IF(H4>0,H6/H4,"") -> 0.31712196 | I14: =IF(I4>0,I6/I4,"") -> 0.34328874 | ... K14: =IF(K4>0,K6/K4,"") -> 0.38846307

Sheet Balance Sheet
A1: ='Profit & Loss'!A1 -> ITC LTD | E1: =UPDATE | J1: SCREENER.IN
A3: Narration | B3: ='Data Sheet'!B56 -> 42825 | C3: ='Data Sheet'!C56 -> 43190 | D3: ='Data Sheet'!D56 -> 43555 | E3: ='Data Sheet'!E56 -> 43921 | F3: ='Data Sheet'!F56 -> 44286
A4: Equity Share Capital | B4: ='Data Sheet'!B57 -> 1214.74 | C4: ='Data Sheet'!C57 -> 1220.43 | D4: ='Data Sheet'!D57 -> 1225.86 | E4: ='Data Sheet'!E57 -> 1229.22 | F4: ='Data Sheet'!F57 -> 1230.88 | G4: ='Data Sheet'!G56 -> 44651 | H4: ='Data Sheet'!H56 -> 45016 | I4: ='Data Sheet'!I56 -> 45382 | J4: ='Data Sheet'!J56 -> 45747 | K4: ='Data Sheet'!K56 -> 46112
A5: Reserves | B5: ='Data Sheet'!B58 -> 45198.19 | C5: ='Data Sheet'!C58 -> 51289.68 | D5: ='Data Sheet'!D58 -> 57915.01 | E5: ='Data Sheet'!E58 -> 64044.04 | F5: ='Data Sheet'!F58 -> 59116.46 | G5: ='Data Sheet'!G57 -> 1232.33 | H5: ='Data Sheet'!H57 -> 1242.8 | I5: ='Data Sheet'!I57 -> 1248.47 | J5: ='Data Sheet'!J57 -> 1251.41 | K5: ='Data Sheet'!K57 -> 1252.95
A6: Borrowings | B6: ='Data Sheet'!B59 -> 45.72 | C6: ='Data Sheet'!C59 -> 35.92 | D6: ='Data Sheet'!D59 -> 13.44 | E6: ='Data Sheet'!E59 -> 277.45 | F6: ='Data Sheet'!F59 -> 270.83 | G6: ='Data Sheet'!G58 -> 61223.24 | H6: ='Data Sheet'!H58 -> 67912.46 | I6: ='Data Sheet'!I58 -> 73258.53 | J6: ='Data Sheet'!J58 -> 68778.64 | K6: ='Data Sheet'!K58 -> 71254.35
A7: Other Liabilities | B7: ='Data Sheet'!B60 -> 9439.67 | C7: ='Data Sheet'!C60 -> 11694.85 | D7: ='Data Sheet'!D60 -> 12584.73 | E7: ='Data Sheet'!E60 -> 11760.04 | F7: ='Data Sheet'!F60 -> 13142.59 | G7: ='Data Sheet'!G59 -> 249.44 | H7: ='Data Sheet'!H59 -> 306.04 | I7: ='Data Sheet'!I59 -> 303.43 | J7: ='Data Sheet'!J59 -> 284.54 | K7: ='Data Sheet'!K59 -> 2399.06
A8: Total | B8: ='Data Sheet'!B61 -> 55898.32 | C8: ='Data Sheet'!C61 -> 64240.88 | D8: ='Data Sheet'!D61 -> 71739.04 | E8: ='Data Sheet'!E61 -> 77310.75 | F8: ='Data Sheet'!F61 -> 73760.76 | G8: ='Data Sheet'!G60 -> 14491.01 | H8: ='Data Sheet'!H60 -> 16369.66 | I8: ='Data Sheet'!I60 -> 16943.54 | J8: ='Data Sheet'!J60 -> 17688.11 | K8: ='Data Sheet'!K60 -> 18886.02
G9: ='Data Sheet'!G61 -> 77196.02 | H9: ='Data Sheet'!H61 -> 85830.96 | I9: ='Data Sheet'!I61 -> 91753.97 | J9: ='Data Sheet'!J61 -> 88002.7 | K9: ='Data Sheet'!K61 -> 93792.38
A10: Net Block | B10: ='Data Sheet'!B62 -> 15893.48 | C10: ='Data Sheet'!C62 -> 16523.96 | D10: ='Data Sheet'!D62 -> 19374.19 | E10: ='Data Sheet'!E62 -> 21713.34 | F10: ='Data Sheet'!F62 -> 23298.48
A11: Capital Work in Progress | B11: ='Data Sheet'!B63 -> 3729.89 | C11: ='Data Sheet'!C63 -> 5508.33 | D11: ='Data Sheet'!D63 -> 4136.42 | E11: ='Data Sheet'!E63 -> 3256.46 | F11: ='Data Sheet'!F63 -> 4011.29 | G11: ='Data Sheet'!G62 -> 24231.59 | H11: ='Data Sheet'!H62 -> 25851.27 | I11: ='Data Sheet'!I62 -> 27820.22 | J11: ='Data Sheet'!J62 -> 21954.85 | K11: ='Data Sheet'!K62 -> 22545
A12: Investments | B12: ='Data Sheet'!B64 -> 17581.38 | C12: ='Data Sheet'!C64 -> 22052.86 | D12: ='Data Sheet'!D64 -> 25043.49 | E12: ='Data Sheet'!E64 -> 28663.35 | F12: ='Data Sheet'!F64 -> 24870.87 | G12: ='Data Sheet'!G63 -> 3225.54 | H12: ='Data Sheet'!H63 -> 3003.3 | I12: ='Data Sheet'!I63 -> 2860.78 | J12: ='Data Sheet'!J63 -> 1090.91 | K12: ='Data Sheet'!K63 -> 1499.41
A13: Other Assets | B13: ='Data Sheet'!B65 -> 18693.57 | C13: ='Data Sheet'!C65 -> 20155.73 | D13: ='Data Sheet'!D65 -> 23184.94 | E13: ='Data Sheet'!E65 -> 23677.6 | F13: ='Data Sheet'!F65 -> 21580.12 | G13: ='Data Sheet'!G64 -> 24841.01 | H13: ='Data Sheet'!H64 -> 29415.02 | I13: ='Data Sheet'!I64 -> 31114.02 | J13: ='Data Sheet'!J64 -> 34719.82 | K13: ='Data Sheet'!K64 -> 38128.43
A14: Total | B14: ='Data Sheet'!B66 -> 55898.32 | C14: ='Data Sheet'!C66 -> 64240.88 | D14: ='Data Sheet'!D66 -> 71739.04 | E14: ='Data Sheet'!E66 -> 77310.75 | F14: ='Data Sheet'!F66 -> 73760.76 | G14: ='Data Sheet'!G65 -> 24897.88 | H14: ='Data Sheet'!H65 -> 27561.37 | I14: ='Data Sheet'!I65 -> 29958.95 | J14: ='Data Sheet'!J65 -> 30237.12 | K14: ='Data Sheet'!K65 -> 31619.54
G15: ='Data Sheet'!G66 -> 77196.02 | H15: ='Data Sheet'!H66 -> 85830.96 | I15: ='Data Sheet'!I66 -> 91753.97 | J15: ='Data Sheet'!J66 -> 88002.7 | K15: ='Data Sheet'!K66 -> 93792.38
A16: Working Capital | B16: =B13-B7 -> 9253.9 | C16: =C13-C7 -> 8460.88 | D16: =D13-D7 -> 10600.21 | E16: =E13-E7 -> 11917.56 | F16: =F13-F7 -> 8437.53
A17: Debtors | B17: ='Data Sheet'!B67 -> 2474.29 | C17: ='Data Sheet'!C67 -> 2682.29 | D17: ='Data Sheet'!D67 -> 4035.28 | E17: ='Data Sheet'!E67 -> 2562.48 | F17: ='Data Sheet'!F67 -> 2501.7 | G17: =G14-G8 -> 10406.87 | H17: =H14-H8 -> 11191.71 | I17: =I14-I8 -> 13015.41 | J17: =J14-J8 -> 12549.01 | K17: =K14-K8 -> 12733.52
A18: Inventory | B18: ='Data Sheet'!B68 -> 8116.1 | C18: ='Data Sheet'!C68 -> 7495.09 | D18: ='Data Sheet'!D68 -> 7859.56 | E18: ='Data Sheet'!E68 -> 8879.33 | F18: ='Data Sheet'!F68 -> 10397.16 | G18: ='Data Sheet'!G67 -> 2461.9 | H18: ='Data Sheet'!H67 -> 2956.17 | I18: ='Data Sheet'!I67 -> 4025.82 | J18: ='Data Sheet'!J67 -> 4719.67 | K18: ='Data Sheet'!K67 -> 3922.86
G19: ='Data Sheet'!G68 -> 10864.15 | H19: ='Data Sheet'!H68 -> 11771.16 | I19: ='Data Sheet'!I68 -> 14152.88 | J19: ='Data Sheet'!J68 -> 15637.56 | K19: ='Data Sheet'!K68 -> 18622.96
A20: Debtor Days | B20: =IF('Profit & Loss'!B4>0,'Balance Sheet'!B17/('Profit & Loss'!B4/365),0) -> 21.116823 | C20: =IF('Profit & Loss'!C4>0,'Balance Sheet'!C17/('Profit & Loss'!C4/365),0) -> 22.53302 | D20: =IF('Profit & Loss'!D4>0,'Balance Sheet'!D17/('Profit & Loss'!D4/365),0) -> 30.469383 | E20: =IF('Profit & Loss'!E4>0,'Balance Sheet'!E17/('Profit & Loss'!E4/365),0) -> 18.938019 | F20: =IF('Profit & Loss'!F4>0,'Balance Sheet'!F17/('Profit & Loss'!F4/365),0) -> 18.537714
A21: Inventory Turnover | B21: =IF('Balance Sheet'!B18>0,'Profit & Loss'!B4/'Balance Sheet'!B18,0) -> 5.2694767 | C21: =IF('Balance Sheet'!C18>0,'Profit & Loss'!C4/'Balance Sheet'!C18,0) -> 5.7969871 | D21: =IF('Balance Sheet'!D18>0,'Profit & Loss'!D4/'Balance Sheet'!D18,0) -> 6.1504181 | E21: =IF('Balance Sheet'!E18>0,'Profit & Loss'!E4/'Balance Sheet'!E18,0) -> 5.5620976 | F21: =IF('Balance Sheet'!F18>0,'Profit & Loss'!F4/'Balance Sheet'!F18,0) -> 4.737587 | G21: =IF('Profit & Loss'!G4>0,'Balance Sheet'!G18/('Profit & Loss'!G4/365),0) -> 14.817385 | H21: =IF('Profit & Loss'!H4>0,'Balance Sheet'!H18/('Profit & Loss'!H4/365),0) -> 15.214563 | I21: =IF('Profit & Loss'!I4>0,'Balance Sheet'!I18/('Profit & Loss'!I4/365),0) -> 21.630831 | J21: =IF('Profit & Loss'!J4>0,'Balance Sheet'!J18/('Profit & Loss'!J4/365),0) -> 22.870462 | K21: =IF('Profit & Loss'!K4>0,'Balance Sheet'!K18/('Profit & Loss'!K4/365),0) -> 18.154849
G22: =IF('Balance Sheet'!G19>0,'Profit & Loss'!G4/'Balance Sheet'!G19,0) -> 5.5820787 | H22: =IF('Balance Sheet'!H19>0,'Profit & Loss'!H4/'Balance Sheet'!H19,0) -> 6.0248123 | I22: =IF('Balance Sheet'!I19>0,'Profit & Loss'!I4/'Balance Sheet'!I19,0) -> 4.7998669 | J22: =IF('Balance Sheet'!J19>0,'Profit & Loss'!J4/'Balance Sheet'!J19,0) -> 4.8168218 | K22: =IF('Balance Sheet'!K19>0,'Profit & Loss'!K4/'Balance Sheet'!K19,0) -> 4.2350088
A23: Return on Equity | B23: =IF(SUM('Balance Sheet'!B4:B5)>0,'Profit & Loss'!B12/SUM('Balance Sheet'!B4:B5),"") -> 0.22169339 | C23: =IF(SUM('Balance Sheet'!C4:C5)>0,'Profit & Loss'!C12/SUM('Balance Sheet'!C4:C5),"") -> 0.21464819 | D23: =IF(SUM('Balance Sheet'!D4:D5)>0,'Profit & Loss'!D12/SUM('Balance Sheet'!D4:D5),"") -> 0.21292095 | E23: =IF(SUM('Balance Sheet'!E4:E5)>0,'Profit & Loss'!E12/SUM('Balance Sheet'!E4:E5),"") -> 0.23449465 | F23: =IF(SUM('Balance Sheet'!F4:F5)>0,'Profit & Loss'!F12/SUM('Balance Sheet'!F4:F5),"") -> 0.21809064
A24: Return on Capital Emp | C24: =IF((B4+B5+B6+C4+C5+C6)>0,('Profit & Loss'!C10+'Profit & Loss'!C9)*2/(B4+B5+B6+C4+C5+C6),"") -> 0.35400589 | D24: =IF((C4+C5+C6+D4+D5+D6)>0,('Profit & Loss'!D10+'Profit & Loss'!D9)*2/(C4+C5+C6+D4+D5+D6),"") -> 0.34415688 | E24: =IF((D4+D5+D6+E4+E5+E6)>0,('Profit & Loss'!E10+'Profit & Loss'!E9)*2/(D4+D5+D6+E4+E5+E6),"") -> 0.32261652 | F24: =IF((E4+E5+E6+F4+F5+F6)>0,('Profit & Loss'!F10+'Profit & Loss'!F9)*2/(E4+E5+E6+F4+F5+F6),"") -> 0.28527066 | G24: =IF(SUM('Balance Sheet'!G5:G6)>0,'Profit & Loss'!G12/SUM('Balance Sheet'!G5:G6),"") -> 0.24405605 | H24: =IF(SUM('Balance Sheet'!H5:H6)>0,'Profit & Loss'!H12/SUM('Balance Sheet'!H5:H6),"") -> 0.27751555 | I24: =IF(SUM('Balance Sheet'!I5:I6)>0,'Profit & Loss'!I12/SUM('Balance Sheet'!I5:I6),"") -> 0.2745887 | J24: =IF(SUM('Balance Sheet'!J5:J6)>0,'Profit & Loss'!J12/SUM('Balance Sheet'!J5:J6),"") -> 0.49616743 | K24: =IF(SUM('Balance Sheet'!K5:K6)>0,'Profit & Loss'!K12/SUM('Balance Sheet'!K5:K6),"") -> 0.28534327
G25: =IF((F4+F5+F6+G5+G6+G7)>0,('Profit & Loss'!G10+'Profit & Loss'!G9)*2/(F4+F5+F6+G5+G6+G7),"") -> 0.33733253 | H25: =IF((G5+G6+G7+H5+H6+H7)>0,('Profit & Loss'!H10+'Profit & Loss'!H9)*2/(G5+G6+G7+H5+H6+H7),"") -> 0.39333609 | I25: =IF((H5+H6+H7+I5+I6+I7)>0,('Profit & Loss'!I10+'Profit & Loss'!I9)*2/(H5+H6+H7+I5+I6+I7),"") -> 0.37429273 | J25: =IF((I5+I6+I7+J5+J6+J7)>0,('Profit & Loss'!J10+'Profit & Loss'!J9)*2/(I5+I6+I7+J5+J6+J7),"") -> 0.57864605 | K25: =IF((J5+J6+J7+K5+K6+K7)>0,('Profit & Loss'!K10+'Profit & Loss'!K9)*2/(J5+J6+J7+K5+K6+K7),"") -> 0.38725211

Sheet Cash Flow
A1: ='Balance Sheet'!A1 -> ITC LTD | E1: =UPDATE | J1: SCREENER.IN
A3: Narration | B3: ='Data Sheet'!B81 -> 42825 | C3: ='Data Sheet'!C81 -> 43190 | D3: ='Data Sheet'!D81 -> 43555 | E3: ='Data Sheet'!E81 -> 43921 | F3: ='Data Sheet'!F81 -> 44286 | G3: ='Data Sheet'!G81 -> 44651 | H3: ='Data Sheet'!H81 -> 45016 | I3: ='Data Sheet'!I81 -> 45382 | ... K3: ='Data Sheet'!K81 -> 46112
A4: Cash from Operating Activity | B4: ='Data Sheet'!B82 -> 10627.31 | C4: ='Data Sheet'!C82 -> 13169.4 | D4: ='Data Sheet'!D82 -> 12583.41 | E4: ='Data Sheet'!E82 -> 14689.66 | F4: ='Data Sheet'!F82 -> 12526.97 | G4: ='Data Sheet'!G82 -> 15775.51 | H4: ='Data Sheet'!H82 -> 18877.55 | I4: ='Data Sheet'!I82 -> 17178.86 | ... K4: ='Data Sheet'!K82 -> 18464.31
A5: Cash from Investing Activity | B5: ='Data Sheet'!B83 -> -3250.93 | C5: ='Data Sheet'!C83 -> -7113.89 | D5: ='Data Sheet'!D83 -> -5545.68 | E5: ='Data Sheet'!E83 -> -6174.02 | F5: ='Data Sheet'!F83 -> 5739.98 | G5: ='Data Sheet'!G83 -> -2238.49 | H5: ='Data Sheet'!H83 -> -5732.29 | I5: ='Data Sheet'!I83 -> 1562.77 | ... K5: ='Data Sheet'!K83 -> -2320.74
A6: Cash from Financing Activity | B6: ='Data Sheet'!B84 -> -7301.03 | C6: ='Data Sheet'!C84 -> -6221.13 | D6: ='Data Sheet'!D84 -> -6868.64 | E6: ='Data Sheet'!E84 -> -8181.48 | F6: ='Data Sheet'!F84 -> -18633.83 | G6: ='Data Sheet'!G84 -> -13580.5 | H6: ='Data Sheet'!H84 -> -13006.03 | I6: ='Data Sheet'!I84 -> -18550.96 | ... K6: ='Data Sheet'!K84 -> -16147.12
A7: Net Cash Flow | B7: ='Data Sheet'!B85 -> 75.35 | C7: ='Data Sheet'!C85 -> -165.62 | D7: ='Data Sheet'!D85 -> 169.09 | E7: ='Data Sheet'!E85 -> 334.16 | F7: ='Data Sheet'!F85 -> -366.88 | G7: ='Data Sheet'!G85 -> -43.48 | H7: ='Data Sheet'!H85 -> 139.23 | I7: ='Data Sheet'!I85 -> 190.67 | ... K7: ='Data Sheet'!K85 -> -3.55

Sheet Customization
A1: How to use it?
A3: You can customize this workbook as you want.
B4: You can add custom formating, add conditional formating, add your own formulas… do ANYTHING.
B5: Please don't edit the "Data Sheet" only.
A7: After customization, you can upload this back on Screener.
B8: Upload on: | C8: https://www.screener.in/excel/
A10: Download your customized workbooks now onwards.
B11: Now whenever you will "Export to excel" from Screener, it will export your customized file.
A14: TESTING:
B15: This is a testing feature currently.
B16: You can report any formula errors on the worksheet at: support@screener.in

Sheet Data Sheet
A1: COMPANY NAME | B1: ITC LTD | E1: =IF(B2<>B3, "A NEW VERSION OF THE WORKSHEET IS AVAILABLE", "")
A2: LATEST VERSION | B2: 2.1 | E2: PLEASE DO NOT MAKE ANY CHANGES TO THIS SHEET
A3: CURRENT VERSION | B3: 2.1
A5: META
A6: Number of shares | B6: =IF(B9>0, B9/B8, 0) -> 1252.9466
A7: Face Value | B7: 1
A8: Current Price | B8: 291.75
A9: Market Capitalization | B9: 365547.17
A15: PROFIT & LOSS
A16: Report Date | B16: 42825 | C16: 43190 | D16: 43555 | E16: 43921 | F16: 44286 | G16: 44651 | H16: 45016 | I16: 45382 | J16: 45747 | K16: 46112
A17: Sales | B17: 42767.6 | C17: 43448.94 | D17: 48339.58 | E17: 49387.7 | F17: 49257.45 | G17: 60644.54 | H17: 70919.03 | I17: 67931.94 | J17: 75323.34 | K17: 78868.4
A18: Raw Material Cost | B18: 15456.59 | C18: 14827.72 | D18: 17623.52 | E18: 18048.6 | F18: 20776.71 | G18: 27071.07 | H18: 29364.36 | I18: 27348.57 | J18: 32704.37 | K18: 35098.34
A19: Change in Inventory | B19: -592.57 | C19: -1027.76 | D19: 203.19 | E19: 703.13 | F19: 645.27 | G19: 686 | H19: 358.59 | I19: 367.77 | J19: 725.65 | K19: 2550.46
A20: Power and Fuel | B20: 584.33 | C20: 653.5 | D20: 746.73 | E20: 780.85 | F20: 699.56 | G20: 889.77 | H20: 1232.34 | I20: 952.9 | J20: 975.35
A21: Other Mfr. Exp | B21: 1683.9 | C21: 1697.62 | D21: 1871.01 | E21: 1908.29 | F21: 1587.18 | G21: 1887.67 | H21: 2327.8 | I21: 2183.76 | J21: 2345.36
A22: Employee Cost | B22: 3631.73 | C22: 3760.9 | D22: 4177.88 | E22: 4295.79 | F22: 4463.33 | G22: 4890.55 | H22: 5736.22 | I22: 5548.53 | J22: 6169.78 | K22: 6781.5
A23: Selling and admin | B23: 4179.74 | C23: 3954.87 | D23: 4546.39 | E23: 4488.63 | F23: 4236.77 | G23: 4858.38 | H23: 5604.08 | I23: 5312.45 | J23: 5793.29
A24: Other Expenses | B24: 1169.23 | C24: 1005.98 | D24: 1039.85 | E24: 1225.13 | F24: 1074.39 | G24: 1109.95 | H24: 1308.56 | I24: 1765.97 | J24: 2221.39 | K24: 12221.11
A25: Other Income | B25: 1758.63 | C25: 2239.81 | D25: 2080.44 | E25: 2417.32 | F25: 2576.95 | G25: 1909.72 | H25: 2097.64 | I25: 3330.45 | J25: 17794.88 | K25: 2511.18
A26: Depreciation | B26: 1152.79 | C26: 1236.28 | D26: 1396.61 | E26: 1644.91 | F26: 1645.59 | G26: 1732.41 | H26: 1809.01 | I26: 1518.05 | J26: 1646.32 | K26: 1710.53
A27: Interest | B27: 49.03 | C27: 115.01 | D27: 71.4 | E27: 81.38 | F27: 57.97 | G27: 59.99 | H27: 77.77 | I27: 39.11 | J27: 45.06 | K27: 85.17
A28: Profit before tax | B28: 16026.32 | C28: 17409.11 | D28: 19149.82 | E28: 20034.57 | F28: 17938.17 | G28: 20740.47 | H28: 25915.12 | I28: 26960.82 | J28: 41942.95 | K28: 28033.39
A29: Tax | B29: 5549.09 | C29: 5916.43 | D29: 6313.92 | E29: 4441.79 | F29: 4555.29 | G29: 5237.34 | H29: 6438.4 | I29: 6209.46 | J29: 6890.47 | K29: 7015.24
A30: Net profit | B30: 10289.44 | C30: 11271.2 | D30: 12592.33 | E30: 15306.23 | F30: 13161.19 | G30: 15242.66 | H30: 19191.66 | I30: 20458.78 | J30: 34746.63 | K30: 20689.47
A31: Dividend Amount | B31: 5770.02 | C31: 6285.21 | D31: 7048.7 | E31: 12476.58 | F31: 13231.96 | G31: 14171.8 | H31: 19263.4 | I31: 17166.46 | J31: 17957.73 | K31: 18167.78
A40: Quarters
A41: Report Date | B41: 45291 | C41: 45382 | D41: 45473 | E41: 45565 | F41: 45657 | G41: 45747 | H41: 45838 | I41: 45930 | J41: 46022 | K41: 46112
A42: Sales | B42: 17195.24 | C42: 17037.8 | D42: 17777.81 | E42: 19990.36 | F42: 18790.17 | G42: 18765 | H42: 21494.79 | I42: 19501.63 | J42: 20047.3 | K42: 17824.68
A43: Expenses | B43: 10985.01 | C43: 10735.73 | D43: 11232.97 | E43: 13438.28 | F43: 12428.27 | G43: 12245.61 | H43: 14678.32 | I43: 12806.94 | J43: 13164.78 | K43: 10900.45
A44: Other Income | B44: 820.26 | C44: 868 | D44: 771.13 | E44: 690.31 | F44: 803.4 | G44: 15391.28 | H44: 750.97 | I44: 738.84 | J44: 321.85 | K44: 699.52
A45: Depreciation | B45: 384.04 | C45: 385.09 | D45: 403.13 | E45: 416.18 | F45: 415.98 | G45: 411.03 | H45: 422.96 | I45: 434.8 | J45: 430.82 | K45: 421.95
A46: Interest | B46: 11.94 | C46: 10.72 | D46: 9.6 | E46: 14.73 | F46: 9.82 | G46: 10.91 | H46: 16.47 | I46: 20.05 | J46: 19.47 | K46: 29.18
A47: Profit before tax | B47: 6634.51 | C47: 6774.26 | D47: 6903.24 | E47: 6811.48 | F47: 6739.5 | G47: 21488.73 | H47: 7128.01 | I47: 6978.68 | J47: 6754.08 | K47: 7172.62
A48: Tax | B48: 1227.99 | C48: 1583.55 | D48: 1726.25 | E48: 1757.05 | F48: 1726.32 | G48: 1680.85 | H48: 1784.6 | I48: 1792.13 | J48: 1735.63 | K48: 1702.88
A49: Net profit | B49: 5335.23 | C49: 5120.55 | D49: 5091.59 | E49: 4992.87 | F49: 4934.8 | G49: 19727.37 | H49: 5244.2 | I49: 5126.11 | J49: 4931.19 | K49: 5387.97
A50: Operating Profit | B50: 6210.23 | C50: 6302.07 | D50: 6544.84 | E50: 6552.08 | F50: 6361.9 | G50: 6519.39 | H50: 6816.47 | I50: 6694.69 | J50: 6882.52 | K50: 6924.23
A55: BALANCE SHEET
A56: Report Date | B56: 42825 | C56: 43190 | D56: 43555 | E56: 43921 | F56: 44286 | G56: 44651 | H56: 45016 | I56: 45382 | J56: 45747 | K56: 46112
A57: Equity Share Capital | B57: 1214.74 | C57: 1220.43 | D57: 1225.86 | E57: 1229.22 | F57: 1230.88 | G57: 1232.33 | H57: 1242.8 | I57: 1248.47 | J57: 1251.41 | K57: 1252.95
A58: Reserves | B58: 45198.19 | C58: 51289.68 | D58: 57915.01 | E58: 64044.04 | F58: 59116.46 | G58: 61223.24 | H58: 67912.46 | I58: 73258.53 | J58: 68778.64 | K58: 71254.35
...

Sheet Sheet1
B3: One Page profile -ITC limited
B13: KEY Financial Matrix | F13: 44651 | G13: 45016 | H13: 45382 | I13: 45747 | J13: 46112
B15: TOTAL SALES | F15: 60644.54 | G15: 70919.03 | H15: 67931.94 | I15: 75323.34 | J15: 78868.4
B16: SALES Growth(y-o-y) | F16: 0.23117498 | G16: 0.16942152 | H16: -0.042119724 | I16: 0.10880596 | J16: 0.047064562
B17: EBITDA%(Y-O-Y) | F17: 0.20852129 | G17: 0.24637895 | H17: -0.020102893 | I17: 0.025882649 | J17: 0.057217162
B18: NP(%) | F18: ='Profit & Loss'!F37 -> 0.15815211 | G18: ='Profit & Loss'!G37 -> 0.25907552 | H18: ='Profit & Loss'!H37 -> 0.066024513 | I18: ='Profit & Loss'!I37 -> 0.69837253 | J18: ='Profit & Loss'!J37 -> -0.40456182
B19: ROE% | F19: ='Balance Sheet'!G24 -> 0.24405605 | G19: ='Balance Sheet'!H24 -> 0.27751555 | H19: ='Balance Sheet'!I24 -> 0.2745887 | I19: ='Balance Sheet'!J24 -> 0.49616743 | J19: ='Balance Sheet'!K24 -> 0.28534327
B20: ROCE% | F20: ='Balance Sheet'!G25 -> 0.33733253 | G20: ='Balance Sheet'!H25 -> 0.39333609 | H20: ='Balance Sheet'!I25 -> 0.37429273 | I20: ='Balance Sheet'!J25 -> 0.57864605 | J20: ='Balance Sheet'!K25 -> 0.38725211
B22: SHAREHOLDING PATTERN | F22: =F13 -> 44651 | G22: =G13 -> 45016 | H22: =H13 -> 45382 | I22: =I13 -> 45747 | J22: =J13 -> 46112
B23: FII | F23: =Sheet2!L14 -> 0.1199 | G23: =Sheet2!M14 -> 0.4335 | H23: =Sheet2!N14 -> 0.4095 | I23: =Sheet2!O14 -> 0.3987 | J23: =Sheet2!P14 -> 0.3483
B24: DII | F24: =Sheet2!L15 -> 0.4277 | G24: =Sheet2!M15 -> 0.4208 | H24: =Sheet2!N15 -> 0.4376 | I24: =Sheet2!O15 -> 0.4519 | J24: =Sheet2!P15 -> 0.4915
B25: GOVERNMENT | F25: =Sheet2!L16 -> 0 | G25: =Sheet2!M16 -> 0.0004 | H25: =Sheet2!N16 -> 0.0004 | I25: =Sheet2!O16 -> 0.0004 | J25: =Sheet2!P16 -> 0.0004
B26: PUBLIC | F26: =Sheet2!L17 -> 0.4524 | G26: =Sheet2!M17 -> 0.1452 | H26: =Sheet2!N17 -> 0.1523 | I26: =Sheet2!O17 -> 0.149 | J26: =Sheet2!P17 -> 0.1596
B28: PEERS COMPARISON
B30: .No. | C30: Name | D30: CMP Rs. | E30: P/E | F30: Mar Cap Rs.Cr. | G30: Div Yld % | H30: NP Qtr Rs.Cr. | I30: Qtr Profit Var % | J30: Sales Qtr Rs.Cr. | K30: ROCE % | L30: Debt Rs.Cr. | M30: EV / EBIT | N30: Sales Rs.Cr.
B31: 1 | C31: Hind. Unilever | D31: 2166.4 | E31: 33.44 | F31: 509015.41 | G31: 1.89 | H31: 2994 | I31: 8.62 | J31: 16351 | K31: 28.42 | L31: 1478 | M31: 35.09 | N31: 64468
B32: 2 | C32: ITC | D32: 290.1 | E32: 17.44 | F32: 363479.77 | G32: 4.96 | H32: 5469.74 | I32: 5.3 | J32: 17824.68 | K32: 38.93 | L32: 2399.06 | M32: 12.77 | N32: 78868.4
B33: 3 | C33: Hindustan Foods | D33: 549.2 | E33: 43.67 | F33: 6654.22 | G33: 0 | H33: 41.55 | I33: 34.17 | J33: 1116.75 | K33: 14.2 | L33: 1088.26 | M33: 26.84 | N33: 4251.04
B34: 4 | C34: Godavari Bioref. | D34: 290.75 | E34: 44.24 | F34: 1487.95 | G34: 0 | H34: 52.88 | I34: -30.03 | J34: 564.1 | K34: 6.55 | L34: 530.76 | M34: 23.42 | N34: 1987.94
B35: 5 | C35: Davangere Sugar | D35: 3.59 | E35: 60.31 | F35: 513.37 | G35: 0 | H35: 1.95 | I35: 0.52 | J35: 83.82 | K35: 5.56 | L35: 250.05 | M35: 19.79 | N35: 238.77
L36: CAPITAL STRUCTURE
N37: (IN CRS)
B38: RECENT UPDATES | M38: MARKET CAPS -363225
M39: DEBT- | N39: 2399
B40: *ITC LTD said they will work on AI segment and removes the all outdated software. | M40: LESS-CASH -30008
B41: *company CEO also confirm that return on equity will grow in the mid of 15 to 20%. | L41: ENTERPRISE VALUE-= | N41: 335477
B42: *company also claim that they will aquire some few companies and want to expand in FMCG sector.
B43: *company also claim that they will probably go with FPO after this year because company needs more funds. | I43: ause company needs fresh funds.
